Workbook

Sheet Planejamento
G1: CONSOLIDADO
C2: CLIENTE | D2: PED. PLACES | E2: TM PLACES | F2: RECEITA PLACES | G2: FAT | H2: PED | I2: TM
B3: 1 | C3: BACIO DI LATTE | G3: 34429130 | H3: 329237 | I3: 104.57248 | J3: BACIO DI LATTE (+200) | L3: jan | M3: jan (real) | N3: Diferença (jan) | O3: Comparativo (jan) | P3: fev | Q3: fev (real) | R3: Diferença (fev) | S3: Comparativo (fev) | T3: mar | U3: mar (real) | V3: Diferença (mar) | W3: Comparativo (mar) | X3: abr | Y3: abr (real) | AA3: Diferença (abr) | AB3: Comparativo (abr) | AC3: mai | AE3: mai (real) | AF3: Diferença (mai) | AH3: Comparativo (mai) | AI3: jun | AJ3: jun (real) | AK3: Diferença (jun) | AL3: Comparativo (jun) | AM3: jul | AN3: jul (real) | AO3: Diferença (jul) | AP3: Comparativo (jul) | AQ3: ago | AR3: ago (real) | AS3: Diferença (ago) | AT3: Comparativo (ago) | AU3: set | AV3: set (real) | AW3: Diferença (set) | AX3: Comparativo (set) | AY3: out | AZ3: out (real) | BA3: Diferença (out) | BB3: Comparativo (out) | BC3: nov | BD3: nov (real) | BE3: Diferença (nov) | BF3: Comparativo (nov) | BG3: dez | BH3: dez (real) | BI3: Diferença (dez) | BJ3: Comparativo (dez) | BK3: 2026 (Projeção) | BL3: 2026 (Projeção até Jun) | BM3: 2026 (Projeção até Jul) | BN3: 2026 (real) | BO3: 2026 (Projeção x Real) | BP3: 2025 | BQ3: -
J5: % do mês no ano | L5: - | M5: - | N5: - | O5: Taxa | P5: - | Q5: - | R5: - | S5: Taxa | T5: 0.04 | U5: =U6/(BK6-(L6 + P6)) -> 0.11865253 | V5: - | W5: Taxa | X5: 0.06 | Y5: =Y6/(BK6-(L6+P6)) -> 0.082262362 | AA5: - | AB5: Taxa | AC5: 0.08 | AE5: =AE6/(BK6-(L6+P6)) -> 0.079638607 | AF5: - | AH5: Taxa | AI5: 0.08 | AJ5: {=IF('Projeção'!AL5:AL1566="", "", 'Projeção'!AL5:AL1566)} -> 0.070108265 | AK5: - | AL5: Taxa | AM5: 0.1 | AN5: {=IF('Projeção'!AU5:AU1566="", "", 'Projeção'!AU5:AU1566)} -> 0.031988516 | AO5: - | AP5: Taxa | AQ5: 0.06 | AR5: =AR6/(BK6-(L6+P6)) -> 0 | AS5: - | AT5: Taxa | AU5: 0.14 | AV5: =AV6/(BK6-(L6+P6)) -> 0 | AW5: - | AX5: Taxa | AY5: 0.14 | AZ5: =AZ6/(BK6-(L6+P6)) -> 0 | BA5: - | BB5: Taxa | BC5: 0.16 | BD5: =BD6/(BK6-(L6+P6)) -> 0 | BE5: - | BF5: Taxa | BG5: 0.14 | BH5: =BH6/(CN6-(AY6 + BC6)) -> 0 | BI5: - | BJ5: Taxa | BK5: =SUM(T5,X5,AC5,AI5,AM5,AQ5,AU5,AY5,BC5,BG5) -> 1 | BL5: =SUM(T5,X5,AC5,AI5) -> 0.26 | BM5: =SUM(T5,X5,AC5,AI5,AM5) -> 0.36 | BN5: =SUM(U5,Y5,AE5,AJ5,AN5,AR5,AV5,AZ5,BD5,BH5) -> 0.38265027
J6: GMV | L6: 2864120 | M6: 3131157.9 | N6: =IFERROR(M6-L6,"-") -> 267037.88 | O6: =IFERROR(M6/L6-1,"-") -> 0.093235577 | P6: 2553655 | Q6: 2769592.7 | R6: =IFERROR(Q6-P6,"-") -> 215937.71 | S6: =IFERROR(Q6/P6-1,"-") -> 0.084560252 | T6: =($BK$6-($L$6+$P$6))*T5 -> 1783289 | U6: 5289793.6 | V6: =IFERROR(U6-T6,"-") -> 3506504.6 | W6: =IFERROR(U6/T6-1,"-") -> 1.9663131 | X6: =($BK$6-($L$6+$P$6))*X5 -> 2674933.5 | Y6: 3667439.1 | AA6: =IFERROR(Y6-X6,"-") -> 992505.64 | AB6: =IFERROR(Y6/X6-1,"-") -> 0.37103937 | AC6: =($BK$6-($L$6+$P$6))*AC5 -> 3566578 | AE6: 3550466.3 | AF6: =IFERROR(AE6-AC6,"-") -> -16111.72 | AH6: =IFERROR(AE6/AC6-1,"-") -> -0.004517417 | AI6: =($BK$6-($L$6+$P$6))*AI5 -> 3566578 | AJ6: 3125582.4 | AK6: =IFERROR(AJ6-AI6,"-") -> -440995.57 | AL6: =IFERROR(AJ6/AI6-1,"-") -> -0.12364669 | AM6: =($BK$6-($L$6+$P$6))*AM5 -> 4458222.5 | AN6: 1426119.2 | AO6: =IFERROR(AN6-AM6,"-") -> -3032103.3 | AP6: =IFERROR(AN6/AM6-1,"-") -> -0.68011484 | AQ6: =($BK$6-($L$6+$P$6))*AQ5 -> 2674933.5 | AS6: =IFERROR(AR6-AQ6,"-") -> -2674933.5 | AT6: =IFERROR(AR6/AQ6-1,"-") -> -1 | AU6: =($BK$6-($L$6+$P$6))*AU5 -> 6241511.5 | AW6: =IFERROR(AV6-AU6,"-") -> -6241511.5 | AX6: =IFERROR(AV6/AU6-1,"-") -> -1 | AY6: =($BK$6-($L$6+$P$6))*AY5 -> 6241511.5 | BA6: =IFERROR(AZ6-AY6,"-") -> -6241511.5 | BB6: =IFERROR(AZ6/AY6-1,"-") -> -1 | BC6: =($BK$6-($L$6+$P$6))*BC5 -> 7133156 | BE6: =IFERROR(BD6-BC6,"-") -> -7133156 | BF6: =IFERROR(BD6/BC6-1,"-") -> -1 | BG6: =($BK$6-($L$6+$P$6))*BG5 -> 6241511.5 | BI6: =IFERROR(BH6-BG6,"-") -> -6241511.5 | BJ6: =IFERROR(BH6/BG6-1,"-") -> -1 | BK6: 50000000 | BL6: =SUM(L6,P6,T6,X6,AC6,AI6) -> 17009154 | BM6: =SUM(L6,P6,T6,X6,AC6,AI6,AM6) -> 21467376 | BN6: =SUM(M6,Q6,U6,Y6,AE6,AJ6,AN6,AR6,AV6,AZ6,BD6,BH6) -> 22960151 | BO6: =IFERROR(BN6/BK6-1,"-") -> -0.54079698 | BP6: 34645067 | BQ6: =BK6/BP6-1 -> 0.44320689
J7: Pedidos | L7: 33527 | M7: 33320 | N7: =IFERROR(M7-L7,"-") -> -207 | O7: =IFERROR(M7/L7-1,"-") -> -0.0061741283 | P7: 28807 | Q7: 28740 | R7: =IFERROR(Q7-P7,"-") -> -67 | S7: =IFERROR(Q7/P7-1,"-") -> -0.0023258236 | T7: =T6/$K$8 -> 19814.322 | U7: 41947 | V7: =IFERROR(U7-T7,"-") -> 22132.678 | W7: =IFERROR(U7/T7-1,"-") -> 1.117004 | X7: =X6/$K$8 -> 29721.483 | Y7: 37395 | AA7: =IFERROR(Y7-X7,"-") -> 7673.5167 | AB7: =IFERROR(Y7/X7-1,"-") -> 0.25818081 | AC7: =AC6/$K$8 -> 39628.644 | AE7: 35712 | AF7: =IFERROR(AE7-AC7,"-") -> -3916.6444 | AH7: =IFERROR(AE7/AC7-1,"-") -> -0.098833672 | AI7: =AI6/$K$8 -> 39628.644 | AJ7: 33203 | AK7: =IFERROR(AJ7-AI7,"-") -> -6425.6444 | AL7: =IFERROR(AJ7/AI7-1,"-") -> -0.16214646 | AM7: =AM6/$K$8 -> 49535.806 | AN7: 14983 | AO7: =IFERROR(AN7-AM7,"-") -> -34552.806 | AP7: =IFERROR(AN7/AM7-1,"-") -> -0.69753192 | AQ7: =AQ6/$K$8 -> 29721.483 | AS7: =IFERROR(AR7-AQ7,"-") -> -29721.483 | AT7: =IFERROR(AR7/AQ7-1,"-") -> -1 | AU7: =AU6/$K$8 -> 69350.128 | AW7: =IFERROR(AV7-AU7,"-") -> -69350.128 | AX7: =IFERROR(AV7/AU7-1,"-") -> -1 | AY7: =AY6/$K$8 -> 69350.128 | BA7: =IFERROR(AZ7-AY7,"-") -> -69350.128 | BB7: =IFERROR(AZ7/AY7-1,"-") -> -1 | BC7: =BC6/$K$8 -> 79257.289 | BE7: =IFERROR(BD7-BC7,"-") -> -79257.289 | BF7: =IFERROR(BD7/BC7-1,"-") -> -1 | BG7: =BG6/$K$8 -> 69350.128 | BI7: =IFERROR(BH7-BG7,"-") -> -69350.128 | BJ7: =IFERROR(BH7/BG7-1,"-") -> -1 | BK7: =SUM(L7,P7,T7,X7,AC7,AI7,AM7,AQ7,AU7,AY7,BC7,BG7) -> 557692.06 | BL7: =SUM(L7,P7,T7,X7,AC7,AI7) -> 191127.09 | BM7: =SUM(L7,P7,T7,X7,AC7,AI7,AM7) -> 240662.9 | BN7: =SUM(M7,Q7,U7,Y7,AE7,AJ7,AN7,AR7,AV7,AZ7,BD7,BH7) -> 225300 | BO7: =(BN7/BK7-1) -> -0.59601361 | BP7: 329232 | BQ7: =BK7/BP7-1 -> 0.69391814
J8: Ticket Médio | K8: 90 | L8: 90 | M8: =IFERROR(M6/M7,"-") -> 93.972325 | N8: =IFERROR(M8-L8,"-") -> 3.9723253 | O8: =IFERROR(M8/L8-1,"-") -> 0.044136948 | P8: 90 | Q8: =Q6/Q7 -> 96.367178 | R8: =IFERROR(Q8-P8,"-") -> 6.3671785 | S8: =IFERROR(Q8/P8-1,"-") -> 0.070746428 | T8: 90 | U8: =IFERROR(U6/U7,"-") -> 126.1066 | V8: =IFERROR(U8-T8,"-") -> 36.1066 | W8: =IFERROR(U8/T8-1,"-") -> 0.40118445 | X8: =IFERROR(X6/X7,"-") -> 90 | Y8: =IFERROR(Y6/Y7,"-") -> 98.072981 | AA8: =IFERROR(Y8-X8,"-") -> 8.0729814 | AB8: =IFERROR(Y8/X8-1,"-") -> 0.089699793 | AC8: 90 | AE8: =IFERROR(AE6/AE7,"-") -> 99.419419 | AF8: =IFERROR(AE8-AC8,"-") -> 9.4194187 | AH8: =IFERROR(AE8/AC8-1,"-") -> 0.10466021 | AI8: =AI6/AI7 -> 90 | AJ8: 94.135543 | AK8: =IFERROR(AJ8-AI8,"-") -> 4.1355429 | AL8: =IFERROR(AJ8/AI8-1,"-") -> 0.045950476 | AM8: =AM6/AM7 -> 90 | AN8: 95.182487 | AO8: =IFERROR(AN8-AM8,"-") -> 5.1824875 | AP8: =IFERROR(AN8/AM8-1,"-") -> 0.057583194 | AQ8: =AQ6/AQ7 -> 90 | AR8: =IFERROR(AR6/AR7,"-") -> - | AS8: =IFERROR(AR8-AQ8,"-") -> - | AT8: =IFERROR(AR8/AQ8-1,"-") -> - | AU8: =AU6/AU7 -> 90 | AV8: =IFERROR(AV6/AV7,"-") -> - | AW8: =IFERROR(AV8-AU8,"-") -> - | AX8: =IFERROR(AV8/AU8-1,"-") -> - | AY8: =AY6/AY7 -> 90 | AZ8: =IFERROR(AZ6/AZ7,"-") -> - | BA8: =IFERROR(AZ8-AY8,"-") -> - | BB8: =IFERROR(AZ8/AY8-1,"-") -> - | BC8: =BC6/BC7 -> 90 | BD8: =IFERROR(BD6/BD7,"-") -> - | BE8: =IFERROR(BD8-BC8,"-") -> - | BF8: =IFERROR(BD8/BC8-1,"-") -> - | BG8: =BG6/BG7 -> 90 | BH8: =IFERROR(BH6/BH7,"-") -> - | BI8: =IFERROR(BH8-BG8,"-") -> - | BJ8: =IFERROR(BH8/BG8-1,"-") -> - | BK8: =BK6/BK7 -> 89.655213 | BL8: =IFERROR(BL6/BL7,"-") -> 88.993942 | BM8: =IFERROR(BM6/BM7,"-") -> 89.201019 | BN8: =BN6/BN7 -> 101.90924 | BO8: =(BN8/BK8-1) -> 0.13667944 | BP8: =BP6/BP7 -> 105.22995 | BQ8: =BK8/BP8-1 -> -0.1480067
J9: Receita Hanzo | K9: 0.049 | L9: =L6*$K$9 -> 140341.88 | M9: =M6*$K$9 -> 153426.74 | N9: =IFERROR(M9-L9,"-") -> 13084.856 | O9: =IFERROR(M9/L9-1,"-") -> 0.093235577 | P9: =P6*$K$9 -> 125129.1 | Q9: =Q6*$K$9 -> 135710.04 | R9: =IFERROR(Q9-P9,"-") -> 10580.948 | S9: =IFERROR(Q9/P9-1,"-") -> 0.084560252 | T9: =T6*$K$9 -> 87381.161 | U9: =U6*$K$9 -> 259199.88 | V9: =IFERROR(U9-T9,"-") -> 171818.72 | W9: =IFERROR(U9/T9-1,"-") -> 1.9663131 | X9: =X6*$K$9 -> 131071.74 | Y9: =Y6*$K$9 -> 179704.52 | AA9: =IFERROR(Y9-X9,"-") -> 48632.776 | AB9: =IFERROR(Y9/X9-1,"-") -> 0.37103937 | AC9: =AC6*$K$9 -> 174762.32 | AE9: =AE6*$K$9 -> 173972.85 | AF9: =IFERROR(AE9-AC9,"-") -> -789.47428 | AH9: =IFERROR(AE9/AC9-1,"-") -> -0.004517417 | AI9: =AI6*$K$9 -> 174762.32 | AJ9: 153153.54 | AK9: =IFERROR(AJ9-AI9,"-") -> -21608.783 | AL9: =IFERROR(AJ9/AI9-1,"-") -> -0.12364669 | AM9: =AM6*$K$9 -> 218452.9 | AN9: 69879.841 | AO9: =IFERROR(AN9-AM9,"-") -> -148573.06 | AP9: =IFERROR(AN9/AM9-1,"-") -> -0.68011484 | AQ9: =AQ6*$K$9 -> 131071.74 | AR9: =AR6*$K$9 -> 0 | AS9: =IFERROR(AR9-AQ9,"-") -> -131071.74 | AT9: =IFERROR(AR9/AQ9-1,"-") -> -1 | AU9: =AU6*$K$9 -> 305834.06 | AV9: =AV6*$K$9 -> 0 | AW9: =IFERROR(AV9-AU9,"-") -> -305834.06 | AX9: =IFERROR(AV9/AU9-1,"-") -> -1 | AY9: =AY6*$K$9 -> 305834.06 | AZ9: =AZ6*$K$9 -> 0 | BA9: =IFERROR(AZ9-AY9,"-") -> -305834.06 | BB9: =IFERROR(AZ9/AY9-1,"-") -> -1 | BC9: =BC6*$K$9 -> 349524.64 | BD9: =BD6*$K$9 -> 0 | BE9: =IFERROR(BD9-BC9,"-") -> -349524.64 | BF9: =IFERROR(BD9/BC9-1,"-") -> -1 | BG9: =BG6*$K$9 -> 305834.06 | BH9: =BH6*$K$9 -> 0 | BI9: =IFERROR(BH9-BG9,"-") -> -305834.06 | BJ9: =IFERROR(BH9/BG9-1,"-") -> -1 | BK9: =SUM(L9,P9,T9,X9,AC9,AI9,AM9,AQ9,AU9,AY9,BC9,BG9) -> 2450000 | BL9: =SUM(L9,P9,T9,X9,AC9,AI9) -> 833448.52 | BM9: =SUM(L9,P9,T9,X9,AC9,AI9,AM9) -> 1051901.4 | BN9: =SUM(M9,Q9,U9,Y9,AE9,AJ9,AN9,AR9,AV9,AZ9,BD9,BH9) -> 1125047.4 | BO9: =(BN9/BK9-1) -> -0.54079698 | BP9: =BP6*0.049 -> 1697608.3 | BQ9: =BK9/BP9-1 -> 0.44320689
P10: 16 | R10: 100 | S10: 180 | T10: 300 | U10: 400 | V10: 450 | W10: 500
J11: CHIQUINHO (+1000) | L11: jan | M11: jan (real) | N11: Diferença (jan) | O11: Comparativo (jan) | P11: fev | Q11: fev (real) | R11: Diferença (fev) | S11: Comparativo (fev) | T11: mar | U11: mar (real) | V11: Diferença (mar) | W11: Comparativo (mar) | X11: abr | Y11: abr (real) | AA11: Diferença (abr) | AB11: Comparativo (abr) | AC11: mai | AE11: mai (real) | AF11: Diferença (mai) | AH11: Comparativo (mai) | AI11: jun | AJ11: jun (real) | AK11: Diferença (jun) | AL11: Comparativo (jun) | AM11: jul | AN11: jul (real) | AO11: Diferença (jul) | AP11: Comparativo (jul) | AQ11: ago | AR11: ago (real) | AS11: Diferença (ago) | AT11: Comparativo (ago) | AU11: set | AV11: set (real) | AW11: Diferença (set) | AX11: Comparativo (set) | AY11: out | AZ11: out (real) | BA11: Diferença (out) | BB11: Comparativo (out) | BC11: nov | BD11: nov (real) | BE11: Diferença (nov) | BF11: Comparativo (nov) | BG11: dez | BH11: dez (real) | BI11: Diferença (dez) | BJ11: Comparativo (dez) | BK11: 2026 (Projeção) | BL11: 2026 (Projeção Jun) | BM11: 2026 (Projeção até Jul) | BN11: 2026 (real) | BO11: 2026 (Projeção x Real) | BP11: 2025 | BQ11: -
B13: 3 | C13: DRUMATTOS/ALIFE NINO | J13: % do mês no ano | L13: - | M13: - | N13: - | O13: Taxa | P13: - | R13: - | S13: Taxa | T13: - | V13: - | W13: Taxa | X13: - | AA13: - | AB13: Taxa | AC13: 0.01 | AE13: =AE14/(BK14-(L14+P14+T14+X14)) -> 0.000267215 | AF13: - | AH13: Taxa | AI13: 0.02 | AJ13: 0.001863735 | AK13: - | AL13: Taxa | AM13: 0.05 | AN13: 8.449e-05 | AO13: - | AP13: Taxa | AQ13: 0.1 | AR13: =AR14/(BK14-(L14+P14+T14+X14)) -> 0 | AS13: - | AT13: Taxa | AU13: 0.12 | AV13: =AV14/(BK14-(L14+P14+T14+X14)) -> 0 | AW13: - | AX13: Taxa | AY13: 0.2 | AZ13: =AZ14/(BK14-(L14+P14+T14+X14)) -> 0 | BA13: - | BB13: Taxa | BC13: 0.25 | BD13: =BD14/(BK14-(L14+P14+T14+X14)) -> 0 | BE13: - | BF13: Taxa | BG13: 0.25 | BH13: =BH14/(BK14-(L14+P14+T14+X14)) -> 0 | BI13: - | BJ13: Taxa | BK13: =SUM(AC13,AI13,AM13,AQ13,AU13,AY13,BC13,BG13) -> 1 | BL13: =SUM(AC13,AI13) -> 0.03 | BM13: =SUM(T13,X13,AC13,AI13,AM13) -> 0.08 | BN13: =SUM(AE13,AJ13,AN13,AR13,AV13,AZ13,BD13,BH13) -> 0.00221544 | BP13: -
J14: GMV | L14: 0 | M14: 345.44 | N14: =IFERROR(M14-L14,"-") -> 345.44 | O14: =IFERROR(M14/L14-1,"-") -> - | P14: 0 | Q14: 511.94 | R14: =IFERROR(Q14-P14,"-") -> 511.94 | S14: =IFERROR(Q14/P14-1,"-") -> - | T14: 0 | U14: 724.91 | V14: =IFERROR(U14-T14,"-") -> 724.91 | W14: =IFERROR(U14/T14-1,"-") -> - | X14: 0 | Y14: 682.92 | AA14: =IFERROR(Y14-X14,"-") -> 682.92 | AB14: =IFERROR(Y14/X14-1,"-") -> - | AC14: =($BK$14-($L$14+$P$14+T14+X14))*AC13 -> 20000 | AE14: 534.43 | AF14: =IFERROR(AE14-AC14,"-") -> -19465.57 | AH14: =IFERROR(AE14/AC14-1,"-") -> -0.9732785 | AI14: =($BK$14-($L$14+$P$14+$T$14+$X$14))*AI13 -> 40000 | AJ14: 3727.47 | AK14: =IFERROR(AJ14-AI14,"-") -> -36272.53 | AL14: =IFERROR(AJ14/AI14-1,"-") -> -0.90681325 | AM14: =($BK$14-($L$14+$P$14+$T$14+$X$14))*AM13 -> 100000 | AN14: 168.98 | AO14: =IFERROR(AN14-AM14,"-") -> -99831.02 | AP14: =IFERROR(AN14/AM14-1,"-") -> -0.9983102 | AQ14: =($BK$14-($L$14+$P$14+$T$14+$X$14))*AQ13 -> 200000 | AS14: =IFERROR(AR14-AQ14,"-") -> -200000 | AT14: =IFERROR(AR14/AQ14-1,"-") -> -1 | AU14: =($BK$14-($L$14+$P$14+$T$14+$X$14))*AU13 -> 240000 | AW14: =IFERROR(AV14-AU14,"-") -> -240000 | AX14: =IFERROR(AV14/AU14-1,"-") -> -1 | AY14: =($BK$14-($L$14+$P$14+$T$14+$X$14))*AY13 -> 400000 | BA14: =IFERROR(AZ14-AY14,"-") -> -400000 | BB14: =IFERROR(AZ14/AY14-1,"-") -> -1 | BC14: =($BK$14-($L$14+$P$14+$T$14+$X$14))*BC13 -> 500000 | BE14: =IFERROR(BD14-BC14,"-") -> -500000 | BF14: =IFERROR(BD14/BC14-1,"-") -> -1 | BG14: =($BK$14-($L$14+$P$14+$T$14+$X$14))*BG13 -> 500000 | BI14: =IFERROR(BH14-BG14,"-") -> -500000 | BJ14: =IFERROR(BH14/BG14-1,"-") -> -1 | BK14: 2000000 | BL14: =SUM(L14,P14,T14,X14,AC14,AI14) -> 60000 | BM14: =SUM(L14,P14,T14,X14,AC14,AI14,AM14) -> 160000 | BN14: =SUM(M14,Q14,U14,Y14,AE14,AJ14,AN14,AR14,AV14,AZ14,BD14,BH14) -> 6696.09 | BO14: =IFERROR(BN14/BK14-1,"-") -> -0.99665196 | BP14: - | BQ14: =IFERROR((BK14/BP14),"-") -> -
J15: Pedidos | L15: 0 | M15: 15 | N15: =IFERROR(M15-L15,"-") -> 15 | O15: =IFERROR(M15/L15-1,"-") -> - | P15: 0 | Q15: 8 | R15: =IFERROR(Q15-P15,"-") -> 8 | S15: =IFERROR(Q15/P15-1,"-") -> - | T15: =T14/$K$16 -> 0 | U15: 9 | V15: =IFERROR(U15-T15,"-") -> 9 | W15: =IFERROR(U15/T15-1,"-") -> - | X15: =X14/$K$16 -> 0 | Y15: 11 | AA15: =IFERROR(Y15-X15,"-") -> 11 | AB15: =IFERROR(Y15/X15-1,"-") -> - | AC15: =AC14/$K$16 -> 666.66667 | AE15: 11 | AF15: =IFERROR(AE15-AC15,"-") -> -655.66667 | AH15: =IFERROR(AE15/AC15-1,"-") -> -0.9835 | AI15: =AI14/$K$16 -> 1333.3333 | AJ15: 154 | AK15: =IFERROR(AJ15-AI15,"-") -> -1179.3333 | AL15: =IFERROR(AJ15/AI15-1,"-") -> -0.8845 | AM15: =AM14/$K$16 -> 3333.3333 | AN15: 5 | AO15: =IFERROR(AN15-AM15,"-") -> -3328.3333 | AP15: =IFERROR(AN15/AM15-1,"-") -> -0.9985 | AQ15: =AQ14/$K$16 -> 6666.6667 | AS15: =IFERROR(AR15-AQ15,"-") -> -6666.6667 | AT15: =IFERROR(AR15/AQ15-1,"-") -> -1 | AU15: =AU14/$K$16 -> 8000 | AW15: =IFERROR(AV15-AU15,"-") -> -8000 | AX15: =IFERROR(AV15/AU15-1,"-") -> -1 | AY15: =AY14/$K$16 -> 13333.333 | BA15: =IFERROR(AZ15-AY15,"-") -> -13333.333 | BB15: =IFERROR(AZ15/AY15-1,"-") -> -1 | BC15: =BC14/$K$16 -> 16666.667 | BE15: =IFERROR(BD15-BC15,"-") -> -16666.667 | BF15: =IFERROR(BD15/BC15-1,"-") -> -1 | BG15: =BG14/$K$16 -> 16666.667 | BI15: =IFERROR(BH15-BG15,"-") -> -16666.667 | BJ15: =IFERROR(BH15/BG15-1,"-") -> -1 | BK15: =SUM(L15,P15,T15,X15,AC15,AI15,AM15,AQ15,AU15,AY15,BC15,BG15) -> 66666.667 | BL15: =SUM(L15,P15,T15,X15,AC15,AI15) -> 2000 | BM15: =SUM(L15,P15,T15,X15,AC15,AI15,AM15) -> 5333.3333 | BN15: =SUM(M15,Q15,U15,Y15,AE15,AJ15,AN15,AR15,AV15,AZ15,BD15,BH15) -> 213 | BO15: =IFERROR(BN15/BK15-1,"-") -> -0.996805 | BP15: - | BQ15: =IFERROR((BK15/BP15),"-") -> -
J16: Ticket Médio | K16: 30 | L16: 30 | M16: =IFERROR(M14/M15,"-") -> 23.029333 | N16: =IFERROR(M16-L16,"-") -> -6.9706667 | O16: =IFERROR(M16/L16-1,"-") -> -0.23235556 | P16: 30 | Q16: =IFERROR(Q14/Q15,"-") -> 63.9925 | R16: =IFERROR(Q16-P16,"-") -> 33.9925 | S16: =IFERROR(Q16/P16-1,"-") -> 1.1330833 | T16: 30 | U16: =IFERROR(U14/U15,"-") -> 80.545556 | V16: =IFERROR(U16-T16,"-") -> 50.545556 | W16: =IFERROR(U16/T16-1,"-") -> 1.6848519 | X16: 30 | Y16: =IFERROR(Y14/Y15,"-") -> 62.083636 | AA16: =IFERROR(Y16-X16,"-") -> 32.083636 | AB16: =IFERROR(Y16/X16-1,"-") -> 1.0694545 | AC16: =AC14/AC15 -> 30 | AE16: =IFERROR(AE14/AE15,"-") -> 48.584545 | AF16: =IFERROR(AE16-AC16,"-") -> 18.584545 | AH16: =IFERROR(AE16/AC16-1,"-") -> 0.61948485 | AI16: =AI14/AI15 -> 30 | AJ16: 24.204351 | AK16: =IFERROR(AJ16-AI16,"-") -> -5.7956494 | AL16: =IFERROR(AJ16/AI16-1,"-") -> -0.19318831 | AM16: =AM14/AM15 -> 30 | AN16: 33.796 | AO16: =IFERROR(AN16-AM16,"-") -> 3.796 | AP16: =IFERROR(AN16/AM16-1,"-") -> 0.12653333 | AQ16: =AQ14/AQ15 -> 30 | AR16: =IFERROR(AR14/AR15,"-") -> - | AS16: =IFERROR(AR16-AQ16,"-") -> - | AT16: =IFERROR(AR16/AQ16-1,"-") -> - | AU16: =AU14/AU15 -> 30 | AV16: =IFERROR(AV14/AV15,"-") -> - | AW16: =IFERROR(AV16-AU16,"-") -> - | AX16: =IFERROR(AV16/AU16-1,"-") -> - | AY16: =AY14/AY15 -> 30 | AZ16: =IFERROR(AZ14/AZ15,"-") -> - | BA16: =IFERROR(AZ16-AY16,"-") -> - | BB16: =IFERROR(AZ16/AY16-1,"-") -> - | BC16: =BC14/BC15 -> 30 | BD16: =IFERROR(BD14/BD15,"-") -> - | BE16: =IFERROR(BD16-BC16,"-") -> - | BF16: =IFERROR(BD16/BC16-1,"-") -> - | BG16: =BG14/BG15 -> 30 | BH16: =IFERROR(BH14/BH15,"-") -> - | BI16: =IFERROR(BH16-BG16,"-") -> - | BJ16: =IFERROR(BH16/BG16-1,"-") -> - | BK16: =BK14/BK15 -> 30 | BL16: =IFERROR(BL14/BL15,"-") -> 30 | BM16: =IFERROR(BM14/BM15,"-") -> 30 | BN16: =BN14/BN15 -> 31.437042 | BO16: =IFERROR(BN16/BK16-1,"-") -> 0.047901408 | BP16: -
J17: Receita Hanzo | K17: 1.4 | L17: =IF(L15=0, 0, MIN(L15, 10000) * 1.4 + MAX(0, MIN(L15, 25000) - 10000) * 1.25 + MAX(0, MIN(L15, 50000) - 25000) * 1.15 + MAX(0, MIN(L15, 100000) - 50000) * 0.9 + MAX(0, MIN(L15, 150000) - 100000) * 0.8 + MAX(0, L15 - 150000) * 0.7 ) -> 0 | M17: =IF(M15=0, 0, MIN(M15, 10000) * 1.4 + MAX(0, MIN(M15, 25000) - 10000) * 1.25 + MAX(0, MIN(M15, 50000) - 25000) * 1.15 + MAX(0, MIN(M15, 100000) - 50000) * 0.9 + MAX(0, MIN(M15, 150000) - 100000) * 0.8 + MAX(0, M15 - 150000) * 0.7 ) -> 21 | N17: =IFERROR(M17-L17,"-") -> 21 | O17: =IFERROR(M17/L17-1,"-") -> - | P17: =IF(P15=0, 0, MIN(P15, 10000) * 1.4 + MAX(0, MIN(P15, 25000) - 10000) * 1.25 + MAX(0, MIN(P15, 50000) - 25000) * 1.15 + MAX(0, MIN(P15, 100000) - 50000) * 0.9 + MAX(0, MIN(P15, 150000) - 100000) * 0.8 + MAX(0, P15 - 150000) * 0.7 ) -> 0 | Q17: =IF(Q15=0, 0, MIN(Q15, 10000) * 1.4 + MAX(0, MIN(Q15, 25000) - 10000) * 1.25 + MAX(0, MIN(Q15, 50000) - 25000) * 1.15 + MAX(0, MIN(Q15, 100000) - 50000) * 0.9 + MAX(0, MIN(Q15, 150000) - 100000) * 0.8 + MAX(0, Q15 - 150000) * 0.7 ) -> 11.2 | R17: =IFERROR(Q17-P17,"-") -> 11.2 | S17: =IFERROR(Q17/P17-1,"-") -> - | T17: =IF(T15=0, 0, MIN(T15, 10000) * 1.4 + MAX(0, MIN(T15, 25000) - 10000) * 1.25 + MAX(0, MIN(T15, 50000) - 25000) * 1.15 + MAX(0, MIN(T15, 100000) - 50000) * 0.9 + MAX(0, MIN(T15, 150000) - 100000) * 0.8 + MAX(0, T15 - 150000) * 0.7 ) -> 0 | U17: =IF(U15=0, 0, MIN(U15, 10000) * 1.4 + MAX(0, MIN(U15, 25000) - 10000) * 1.25 + MAX(0, MIN(U15, 50000) - 25000) * 1.15 + MAX(0, MIN(U15, 100000) - 50000) * 0.9 + MAX(0, MIN(U15, 150000) - 100000) * 0.8 + MAX(0, U15 - 150000) * 0.7 ) -> 12.6 | V17: =IFERROR(U17-T17,"-") -> 12.6 | W17: =IFERROR(U17/T17-1,"-") -> - | X17: =IF(X15=0, 0, MIN(X15, 10000) * 1.4 + MAX(0, MIN(X15, 25000) - 10000) * 1.25 + MAX(0, MIN(X15, 50000) - 25000) * 1.15 + MAX(0, MIN(X15, 100000) - 50000) * 0.9 + MAX(0, MIN(X15, 150000) - 100000) * 0.8 + MAX(0, X15 - 150000) * 0.7 ) -> 0 | Y17: =IF(Y15=0, 0, MIN(Y15, 10000) * 1.4 + MAX(0, MIN(Y15, 25000) - 10000) * 1.25 + MAX(0, MIN(Y15, 50000) - 25000) * 1.15 + MAX(0, MIN(Y15, 100000) - 50000) * 0.9 + MAX(0, MIN(Y15, 150000) - 100000) * 0.8 + MAX(0, Y15 - 150000) * 0.7 ) -> 15.4 | AA17: =IFERROR(Y17-X17,"-") -> 15.4 | AB17: =IFERROR(Y17/X17-1,"-") -> - | AC17: =IF(AC15=0, 0, MIN(AC15, 10000) * 1.4 + MAX(0, MIN(AC15, 25000) - 10000) * 1.25 + MAX(0, MIN(AC15, 50000) - 25000) * 1.15 + MAX(0, MIN(AC15, 100000) - 50000) * 0.9 + MAX(0, MIN(AC15, 150000) - 100000) * 0.8 + MAX(0, AC15 - 150000) * 0.7 ) -> 933.33333 | AE17: =IF(AE15=0, 0, MIN(AE15, 10000) * 1.4 + MAX(0, MIN(AE15, 25000) - 10000) * 1.25 + MAX(0, MIN(AE15, 50000) - 25000) * 1.15 + MAX(0, MIN(AE15, 100000) - 50000) * 0.9 + MAX(0, MIN(AE15, 150000) - 100000) * 0.8 + MAX(0, AE15 - 150000) * 0.7 ) -> 15.4 | AF17: =IFERROR(AE17-AC17,"-") -> -917.93333 | AH17: =IFERROR(AE17/AC17-1,"-") -> -0.9835 | AI17: =IF(AI15=0, 0, MIN(AI15, 10000) * 1.4 + MAX(0, MIN(AI15, 25000) - 10000) * 1.25 + MAX(0, MIN(AI15, 50000) - 25000) * 1.15 + MAX(0, MIN(AI15, 100000) - 50000) * 0.9 + MAX(0, MIN(AI15, 150000) - 100000) * 0.8 + MAX(0, AI15 - 150000) * 0.7 ) -> 1866.6667 | AJ17: 215.6 | AK17: =IFERROR(AJ17-AI17,"-") -> -1651.0667 | AL17: =IFERROR(AJ17/AI17-1,"-") -> -0.8845 | AM17: =IF(AM15=0, 0, MIN(AM15, 10000) * 1.4 + MAX(0, MIN(AM15, 25000) - 10000) * 1.25 + MAX(0, MIN(AM15, 50000) - 25000) * 1.15 + MAX(0, MIN(AM15, 100000) - 50000) * 0.9 + MAX(0, MIN(AM15, 150000) - 100000) * 0.8 + MAX(0, AM15 - 150000) * 0.7 ) -> 4666.6667 | AN17: 7 | AO17: =IFERROR(AN17-AM17,"-") -> -4659.6667 | AP17: =IFERROR(AN17/AM17-1,"-") -> -0.9985 | AQ17: =IF(AQ15=0, 0, MIN(AQ15, 10000) * 1.4 + MAX(0, MIN(AQ15, 25000) - 10000) * 1.25 + MAX(0, MIN(AQ15, 50000) - 25000) * 1.15 + MAX(0, MIN(AQ15, 100000) - 50000) * 0.9 + MAX(0, MIN(AQ15, 150000) - 100000) * 0.8 + MAX(0, AQ15 - 150000) * 0.7 ) -> 9333.3333 | AR17: =IF(AR15=0, 0, MIN(AR15, 10000) * 1.4 + MAX(0, MIN(AR15, 25000) - 10000) * 1.25 + MAX(0, MIN(AR15, 50000) - 25000) * 1.15 + MAX(0, MIN(AR15, 100000) - 50000) * 0.9 + MAX(0, MIN(AR15, 150000) - 100000) * 0.8 + MAX(0, AR15 - 150000) * 0.7 ) -> 0 | AS17: =IFERROR(AR17-AQ17,"-") -> -9333.3333 | AT17: =IFERROR(AR17/AQ17-1,"-") -> -1 | AU17: =IF(AU15=0, 0, MIN(AU15, 10000) * 1.4 + MAX(0, MIN(AU15, 25000) - 10000) * 1.25 + MAX(0, MIN(AU15, 50000) - 25000) * 1.15 + MAX(0, MIN(AU15, 100000) - 50000) * 0.9 + MAX(0, MIN(AU15, 150000) - 100000) * 0.8 + MAX(0, AU15 - 150000) * 0.7 ) -> 11200 | AV17: =IF(AV15=0, 0, MIN(AV15, 10000) * 1.4 + MAX(0, MIN(AV15, 25000) - 10000) * 1.25 + MAX(0, MIN(AV15, 50000) - 25000) * 1.15 + MAX(0, MIN(AV15, 100000) - 50000) * 0.9 + MAX(0, MIN(AV15, 150000) - 100000) * 0.8 + MAX(0, AV15 - 150000) * 0.7 ) -> 0 | AW17: =IFERROR(AV17-AU17,"-") -> -11200 | AX17: =IFERROR(AV17/AU17-1,"-") -> -1 | AY17: =IF(AY15=0, 0, MIN(AY15, 10000) * 1.4 + MAX(0, MIN(AY15, 25000) - 10000) * 1.25 + MAX(0, MIN(AY15, 50000) - 25000) * 1.15 + MAX(0, MIN(AY15, 100000) - 50000) * 0.9 + MAX(0, MIN(AY15, 150000) - 100000) * 0.8 + MAX(0, AY15 - 150000) * 0.7 ) -> 18166.667 | AZ17: =IF(AZ15=0, 0, MIN(AZ15, 10000) * 1.4 + MAX(0, MIN(AZ15, 25000) - 10000) * 1.25 + MAX(0, MIN(AZ15, 50000) - 25000) * 1.15 + MAX(0, MIN(AZ15, 100000) - 50000) * 0.9 + MAX(0, MIN(AZ15, 150000) - 100000) * 0.8 + MAX(0, AZ15 - 150000) * 0.7 ) -> 0 | BA17: =IFERROR(AZ17-AY17,"-") -> -18166.667 | BB17: =IFERROR(AZ17/AY17-1,"-") -> -1 | BC17: =IF(BC15=0, 0, MIN(BC15, 10000) * 1.4 + MAX(0, MIN(BC15, 25000) - 10000) * 1.25 + MAX(0, MIN(BC15, 50000) - 25000) * 1.15 + MAX(0, MIN(BC15, 100000) - 50000) * 0.9 + MAX(0, MIN(BC15, 150000) - 100000) * 0.8 + MAX(0, BC15 - 150000) * 0.7 ) -> 22333.333 | BD17: =IF(BD15=0, 0, MIN(BD15, 10000) * 1.4 + MAX(0, MIN(BD15, 25000) - 10000) * 1.25 + MAX(0, MIN(BD15, 50000) - 25000) * 1.15 + MAX(0, MIN(BD15, 100000) - 50000) * 0.9 + MAX(0, MIN(BD15, 150000) - 100000) * 0.8 + MAX(0, BD15 - 150000) * 0.7 ) -> 0 | BE17: =IFERROR(BD17-BC17,"-") -> -22333.333 | BF17: =IFERROR(BD17/BC17-1,"-") -> -1 | BG17: =IF(BG15=0, 0, MIN(BG15, 10000) * 1.4 + MAX(0, MIN(BG15, 25000) - 10000) * 1.25 + MAX(0, MIN(BG15, 50000) - 25000) * 1.15 + MAX(0, MIN(BG15, 100000) - 50000) * 0.9 + MAX(0, MIN(BG15, 150000) - 100000) * 0.8 + MAX(0, BG15 - 150000) * 0.7 ) -> 22333.333 | BH17: =IF(BH15=0, 0, MIN(BH15, 10000) * 1.4 + MAX(0, MIN(BH15, 25000) - 10000) * 1.25 + MAX(0, MIN(BH15, 50000) - 25000) * 1.15 + MAX(0, MIN(BH15, 100000) - 50000) * 0.9 + MAX(0, MIN(BH15, 150000) - 100000) * 0.8 + MAX(0, BH15 - 150000) * 0.7 ) -> 0 | BI17: =IFERROR(BH17-BG17,"-") -> -22333.333 | BJ17: =IFERROR(BH17/BG17-1,"-") -> -1 | BK17: =SUM(L17,P17,T17,X17,AC17,AI17,AM17,AQ17,AU17,AY17,BC17,BG17) -> 90833.333 | BL17: =SUM(L17,P17,T17,X17,AC17,AI17) -> 2800 | BM17: =SUM(L17,P17,T17,X17,AC17,AI17,AM17) -> 7466.6667 | BN17: =SUM(M17,Q17,U17,Y17,AE17,AJ17,AN17,AR17,AV17,AZ17,BD17,BH17) -> 298.2 | BO17: =IFERROR(BN17/BK17-1,"-") -> -0.99671706 | BP17: - | BQ17: =IFERROR((BK17/BP17),"-") -> -
J19: CAMARADA CAMARÃO | L19: jan | M19: jan (real) | N19: Diferença (jan) | O19: Comparativo (jan) | P19: fev | Q19: fev (real) | R19: Diferença (fev) | S19: Comparativo (fev) | T19: mar | U19: mar (real) | V19: Diferença (mar) | W19: Comparativo (mar) | X19: abr | Y19: abr (real) | AA19: Diferença (abr) | AB19: Comparativo (abr) | AC19: mai | AE19: mai (real) | AF19: Diferença (mai) | AH19: Comparativo (mai) | AI19: jun | AJ19: jun (real) | AK19: Diferença (jun) | AL19: Comparativo (jun) | AM19: jul | AN19: jul (real) | AO19: Diferença (jul) | AP19: Comparativo (jul) | AQ19: ago | AR19: ago (real) | AS19: Diferença (ago) | AT19: Comparativo (ago) | AU19: set | AV19: set (real) | AW19: Diferença (set) | AX19: Comparativo (set) | AY19: out | AZ19: out (real) | BA19: Diferença (out) | BB19: Comparativo (out) | BC19: nov | BD19: nov (real) | BE19: Diferença (nov) | BF19: Comparativo (nov) | BG19: dez | BH19: dez (real) | BI19: Diferença (dez) | BJ19: Comparativo (dez) | BK19: 2026 (Projeção) | BL19: 2026 (Projeção Jun) | BM19: 2026 (Projeção até Jul) | BN19: 2026 (real) | BO19: 2026 (Projeção x Real) | BP19: 2025 | BQ19: -
B21: 4 | C21: ESFIHA IMIGRANTES | D21: =15000*12*4 -> 720000 | E21: 92 | F21: =E21*D21 -> 66240000 | G21: 1632825.8 | H21: 15759 | I21: 103.61227 | J21: % do mês no ano | L21: - | M21: - | N21: - | O21: Taxa | P21: - | Q21: - | R21: - | S21: Taxa | T21: - | V21: - | W21: Taxa | X21: - | AA21: - | AB21: Taxa | AC21: 0.01 | AE21: =AE22/(BK22-(L22+P22+T22+X22)) -> 1e-05 | AF21: - | AH21: Taxa | AI21: 0.05 | AJ21: 2.21975e-05 | AK21: - | AL21: Taxa | AM21: 0.1 | AN21: 0.0005073175 | AO21: - | AP21: Taxa | AQ21: 0.14 | AR21: =AR22/(BK22-(L22+P22+T22+X22)) -> 0 | AS21: - | AT21: Taxa | AU21: 0.15 | AV21: =AV22/(BK22-(L22+P22+T22+X22)) -> 0 | AW21: - | AX21: Taxa | AY21: 0.2 | AZ21: =AZ22/(BK22-(L22+P22+T22+X22)) -> 0 | BA21: - | BB21: Taxa | BC21: 0.2 | BD21: =BD22/(BK22-(L22+P22+T22+X22)) -> 0 | BE21: - | BF21: Taxa | BG21: 0.15 | BH21: =BH22/(BK22-(L22+P22+T22+X22)) -> 0 | BI21: - | BJ21: Taxa | BK21: =SUM(AC21,AI21,AM21,AQ21,AU21,AY21,BC21,BG21) -> 1 | BL21: =SUM(AC21,AI21) -> 0.06 | BM21: =SUM(T21,X21,AC21,AI21,AM21) -> 0.16 | BN21: =SUM(AE21,AJ21,AN21,AR21,AV21,AZ21,BD21,BH21) -> 0.000539515 | BP21: -
J22: GMV | L22: 0 | N22: =IFERROR(M22-L22,"-") -> 0 | O22: =IFERROR(M22/L22-1,"-") -> - | P22: 0 | R22: =IFERROR(Q22-P22,"-") -> 0 | S22: =IFERROR(Q22/P22-1,"-") -> - | T22: 0 | V22: =IFERROR(U22-T22,"-") -> 0 | W22: =IFERROR(U22/T22-1,"-") -> - | X22: 0 | AA22: =IFERROR(Y22-X22,"-") -> 0 | AB22: =IFERROR(Y22/X22-1,"-") -> - | AC22: =($BK$22-($L$22+$P$22+T22+X22))*AC21 -> 40000 | AE22: 40 | AF22: =IFERROR(AE22-AC22,"-") -> -39960 | AH22: =IFERROR(AE22/AC22-1,"-") -> -0.999 | AI22: =($BK$22-($L$22+$P$22+$T$22+$X$22))*AI21 -> 200000 | AK22: =IFERROR(AJ22-AI22,"-") -> -200000 | AL22: =IFERROR(AJ22/AI22-1,"-") -> -1 | AM22: =($BK$22-($L$22+$P$22+$T$22+$X$22))*AM21 -> 400000 | AN22: 2029.27 | AO22: =IFERROR(AN22-AM22,"-") -> -397970.73 | AP22: =IFERROR(AN22/AM22-1,"-") -> -0.99492682 | AQ22: =($BK$22-($L$22+$P$22+$T$22+$X$22))*AQ21 -> 560000 | AS22: =IFERROR(AR22-AQ22,"-") -> -560000 | AT22: =IFERROR(AR22/AQ22-1,"-") -> -1 | AU22: =($BK$22-($L$22+$P$22+$T$22+$X$22))*AU21 -> 600000 | AW22: =IFERROR(AV22-AU22,"-") -> -600000 | AX22: =IFERROR(AV22/AU22-1,"-") -> -1 | AY22: =($BK$22-($L$22+$P$22+$T$22+$X$22))*AY21 -> 800000 | BA22: =IFERROR(AZ22-AY22,"-") -> -800000 | BB22: =IFERROR(AZ22/AY22-1,"-") -> -1 | BC22: =($BK$22-($L$22+$P$22+$T$22+$X$22))*BC21 -> 800000 | BE22: =IFERROR(BD22-BC22,"-") -> -800000 | BF22: =IFERROR(BD22/BC22-1,"-") -> -1 | BG22: =($BK$22-($L$22+$P$22+$T$22+$X$22))*BG21 -> 600000 | BI22: =IFERROR(BH22-BG22,"-") -> -600000 | BJ22: =IFERROR(BH22/BG22-1,"-") -> -1 | BK22: 4000000 | BL22: =SUM(L22,P22,T22,X22,AC22,AI22) -> 240000 | BM22: =SUM(L22,P22,T22,X22,AC22,AI22,AM22) -> 640000 | BN22: =SUM(M22,Q22,U22,Y22,AE22,AJ22,AN22,AR22,AV22,AZ22,BD22,BH22) -> 2069.27 | BO22: =IFERROR(BN22/BK22-1,"-") -> -0.99948268 | BP22: - | BQ22: =IFERROR((BK22/BP22),"-") -> -
J23: Pedidos | L23: =L22/$K$24 -> 0 | N23: =IFERROR(M23-L23,"-") -> 0 | O23: =IFERROR(M23/L23-1,"-") -> - | P23: =P22/$K$24 -> 0 | R23: =IFERROR(Q23-P23,"-") -> 0 | S23: =IFERROR(Q23/P23-1,"-") -> - | T23: =T22/$K$24 -> 0 | V23: =IFERROR(U23-T23,"-") -> 0 | W23: =IFERROR(U23/T23-1,"-") -> - | X23: =X22/$K$24 -> 0 | AA23: =IFERROR(Y23-X23,"-") -> 0 | AB23: =IFERROR(Y23/X23-1,"-") -> - | AC23: =AC22/$K$24 -> 222.22222 | AE23: 2 | AF23: =IFERROR(AE23-AC23,"-") -> -220.22222 | AH23: =IFERROR(AE23/AC23-1,"-") -> -0.991 | AI23: =AI22/$K$24 -> 1111.1111 | AK23: =IFERROR(AJ23-AI23,"-") -> -1111.1111 | AL23: =IFERROR(AJ23/AI23-1,"-") -> -1 | AM23: =AM22/$K$24 -> 2222.2222 | AN23: 16 | AO23: =IFERROR(AN23-AM23,"-") -> -2206.2222 | AP23: =IFERROR(AN23/AM23-1,"-") -> -0.9928 | AQ23: =AQ22/$K$24 -> 3111.1111 | AS23: =IFERROR(AR23-AQ23,"-") -> -3111.1111 | AT23: =IFERROR(AR23/AQ23-1,"-") -> -1 | AU23: =AU22/$K$24 -> 3333.3333 | AW23: =IFERROR(AV23-AU23,"-") -> -3333.3333 | AX23: =IFERROR(AV23/AU23-1,"-") -> -1 | AY23: =AY22/$K$24 -> 4444.4444 | BA23: =IFERROR(AZ23-AY23,"-") -> -4444.4444 | BB23: =IFERROR(AZ23/AY23-1,"-") -> -1 | BC23: =BC22/$K$24 -> 4444.4444 | BE23: =IFERROR(BD23-BC23,"-") -> -4444.4444 | BF23: =IFERROR(BD23/BC23-1,"-") -> -1 | BG23: =BG22/$K$24 -> 3333.3333 | BI23: =IFERROR(BH23-BG23,"-") -> -3333.3333 | BJ23: =IFERROR(BH23/BG23-1,"-") -> -1 | BK23: =SUM(L23,P23,T23,X23,AC23,AI23,AM23,AQ23,AU23,AY23,BC23,BG23) -> 22222.222 | BL23: =SUM(L23,P23,T23,X23,AC23,AI23) -> 1333.3333 | BM23: =SUM(L23,P23,T23,X23,AC23,AI23,AM23) -> 3555.5556 | BN23: =SUM(M23,Q23,U23,Y23,AE23,AJ23,AN23,AR23,AV23,AZ23,BD23,BH23) -> 18 | BO23: =IFERROR(BN23/BK23-1,"-") -> -0.99919 | BP23: - | BQ23: =IFERROR((BK23/BP23),"-") -> -
J24: Ticket Médio | K24: 180 | L24: 180 | M24: =IFERROR(M22/M23,"-") -> - | N24: =IFERROR(M24-L24,"-") -> - | O24: =IFERROR(M24/L24-1,"-") -> - | P24: 180 | Q24: =IFERROR(Q22/Q23,"-") -> - | R24: =IFERROR(Q24-P24,"-") -> - | S24: =IFERROR(Q24/P24-1,"-") -> - | T24: 180 | U24: =IFERROR(U22/U23,"-") -> - | V24: =IFERROR(U24-T24,"-") -> - | W24: =IFERROR(U24/T24-1,"-") -> - | X24: 180 | Y24: =IFERROR(Y22/Y23,"-") -> - | AA24: =IFERROR(Y24-X24,"-") -> - | AB24: =IFERROR(Y24/X24-1,"-") -> - | AC24: =AC22/AC23 -> 180 | AE24: =IFERROR(AE22/AE23,"-") -> 20 | AF24: =IFERROR(AE24-AC24,"-") -> -160 | AH24: =IFERROR(AE24/AC24-1,"-") -> -0.88888889 | AI24: =AI22/AI23 -> 180 | AJ24: - | AK24: =IFERROR(AJ24-AI24,"-") -> - | AL24: =IFERROR(AJ24/AI24-1,"-") -> - | AM24: =AM22/AM23 -> 180 | AN24: 126.82937 | AO24: =IFERROR(AN24-AM24,"-") -> -53.170625 | AP24: =IFERROR(AN24/AM24-1,"-") -> -0.29539236 | AQ24: =AQ22/AQ23 -> 180 | AR24: =IFERROR(AR22/AR23,"-") -> - | AS24: =IFERROR(AR24-AQ24,"-") -> - | AT24: =IFERROR(AR24/AQ24-1,"-") -> - | AU24: =AU22/AU23 -> 180 | AV24: =IFERROR(AV22/AV23,"-") -> - | AW24: =IFERROR(AV24-AU24,"-") -> - | AX24: =IFERROR(AV24/AU24-1,"-") -> - | AY24: =AY22/AY23 -> 180 | AZ24: =IFERROR(AZ22/AZ23,"-") -> - | BA24: =IFERROR(AZ24-AY24,"-") -> - | BB24: =IFERROR(AZ24/AY24-1,"-") -> - | BC24: =BC22/BC23 -> 180 | BD24: =IFERROR(BD22/BD23,"-") -> - | BE24: =IFERROR(BD24-BC24,"-") -> - | BF24: =IFERROR(BD24/BC24-1,"-") -> - | BG24: =BG22/BG23 -> 180 | BH24: =IFERROR(BH22/BH23,"-") -> - | BI24: =IFERROR(BH24-BG24,"-") -> - | BJ24: =IFERROR(BH24/BG24-1,"-") -> - | BK24: =BK22/BK23 -> 180 | BL24: =IFERROR(BL22/BL23,"-") -> 180 | BM24: =IFERROR(BM22/BM23,"-") -> 180 | BN24: =IFERROR(BN22/BN23,"-") -> 114.95944 | BO24: =IFERROR(BN24/BK24-1,"-") -> -0.36133642
J25: Receita Hanzo | K25: 4.5 | L25: =$K$25*L23 -> 0 | M25: =$K$25*M23 -> 0 | N25: =IFERROR(M25-L25,"-") -> 0 | O25: =IFERROR(M25/L25-1,"-") -> - | P25: =$K$25*P23 -> 0 | Q25: =$K$25*Q23 -> 0 | R25: =IFERROR(Q25-P25,"-") -> 0 | S25: =IFERROR(Q25/P25-1,"-") -> - | T25: =$K$25*T23 -> 0 | U25: =$K$25*U23 -> 0 | V25: =IFERROR(U25-T25,"-") -> 0 | W25: =IFERROR(U25/T25-1,"-") -> - | X25: =$K$25*X23 -> 0 | Y25: =$K$25*Y23 -> 0 | AA25: =IFERROR(Y25-X25,"-") -> 0 | AB25: =IFERROR(Y25/X25-1,"-") -> - | AC25: =$K$25*AC23 -> 1000 | AE25: =$K$25*AE23 -> 9 | AF25: =IFERROR(AE25-AC25,"-") -> -991 | AH25: =IFERROR(AE25/AC25-1,"-") -> -0.991 | AI25: =$K$25*AI23 -> 5000 | AJ25: 0 | AK25: =IFERROR(AJ25-AI25,"-") -> -5000 | AL25: =IFERROR(AJ25/AI25-1,"-") -> -1 | AM25: =$K$25*AM23 -> 10000 | AN25: 72 | AO25: =IFERROR(AN25-AM25,"-") -> -9928 | AP25: =IFERROR(AN25/AM25-1,"-") -> -0.9928 | AQ25: =$K$25*AQ23 -> 14000 | AR25: =$K$25*AR23 -> 0 | AS25: =IFERROR(AR25-AQ25,"-") -> -14000 | AT25: =IFERROR(AR25/AQ25-1,"-") -> -1 | AU25: =$K$25*AU23 -> 15000 | AV25: =$K$25*AV23 -> 0 | AW25: =IFERROR(AV25-AU25,"-") -> -15000 | AX25: =IFERROR(AV25/AU25-1,"-") -> -1 | AY25: =$K$25*AY23 -> 20000 | AZ25: =$K$25*AZ23 -> 0 | BA25: =IFERROR(AZ25-AY25,"-") -> -20000 | BB25: =IFERROR(AZ25/AY25-1,"-") -> -1 | BC25: =$K$25*BC23 -> 20000 | BD25: =$K$25*BD23 -> 0 | BE25: =IFERROR(BD25-BC25,"-") -> -20000 | BF25: =IFERROR(BD25/BC25-1,"-") -> -1 | BG25: =$K$25*BG23 -> 15000 | BH25: =$K$25*BH23 -> 0 | BI25: =IFERROR(BH25-BG25,"-") -> -15000 | BJ25: =IFERROR(BH25/BG25-1,"-") -> -1 | BK25: =SUM(L25,P25,T25,X25,AC25,AI25,AM25,AQ25,AU25,AY25,BC25,BG25) -> 100000 | BL25: =SUM(L25,P25,T25,X25,AC25,AI25) -> 6000 | BM25: =SUM(L25,P25,T25,X25,AC25,AI25,AM25) -> 16000 | BN25: =SUM(M25,Q25,U25,Y25,AE25,AJ25,AN25,AR25,AV25,AZ25,BD25,BH25) -> 81 | BO25: =IFERROR(BN25/BK25-1,"-") -> -0.99919 | BP25: - | BQ25: =IFERROR((BK25/BP25),"-") -> -
J27: ESFIHA IMIGRANTES (4) | L27: jan | M27: jan (real) | N27: Diferença (jan) | O27: Comparativo (jan) | P27: fev | Q27: fev (real) | R27: Diferença (fev) | S27: Comparativo (fev) | T27: mar | U27: mar (real) | V27: Diferença (mar) | W27: Comparativo (mar) | X27: abr | Y27: abr (real) | AA27: Diferença (abr) | AB27: Comparativo (abr) | AC27: mai | AE27: mai (real) | AF27: Diferença (mai) | AH27: Comparativo (mai) | AI27: jun | AJ27: jun (real) | AK27: Diferença (jun) | AL27: Comparativo (jun) | AM27: jul | AN27: jul (real) | AO27: Diferença (jul) | AP27: Comparativo (jul) | AQ27: ago | AR27: ago (real) | AS27: Diferença (ago) | AT27: Comparativo (ago) | AU27: set | AV27: set (real) | AW27: Diferença (set) | AX27: Comparativo (set) | AY27: out | AZ27: out (real) | BA27: Diferença (out) | BB27: Comparativo (out) | BC27: nov | BD27: nov (real) | BE27: Diferença (nov) | BF27: Comparativo (nov) | BG27: dez | BH27: dez (real) | BI27: Diferença (dez) | BJ27: Comparativo (dez) | BK27: 2026 (Projeção) | BL27: 2026 (Projeção Jun) | BM27: 2026 (Projeção até Jul) | BN27: 2026 (real) | BO27: 2026 (Projeção x Real) | BP27: 2025
B29: 5 | C29: FROOTY | D29: =28*2*12 -> 672 | F29: =D29*35 -> 23520 | G29: 14.9 | H29: 1 | I29: 14.9 | J29: % do mês no ano | L29: - | M29: - | N29: - | O29: Taxa | P29: - | Q29: - | R29: - | S29: Taxa | T29: 0.03 | U29: =U30/(BK30-(L30 + P30)) -> 0.028796126 | V29: - | W29: Taxa | X29: 0.03 | Y29: =Y30/(BK30-(L30+P30)) -> 0.022408562 | AA29: - | AB29: Taxa | AC29: 0.05 | AE29: =AE30/(BK30-(L30+P30)) -> 0.02664966 | AF29: - | AH29: Taxa | AI29: 0.08 | AJ29: 0.026941763 | AK29: - | AL29: Taxa | AM29: 0.13 | AN29: 0.016667338 | AO29: - | AP29: Taxa | AQ29: 0.13 | AR29: =AR30/(BK30-(L30+P30)) -> 0 | AS29: - | AT29: Taxa | AU29: 0.13 | AV29: =AV30/(BK30-(L30+P30)) -> 0 | AW29: - | AX29: Taxa | AY29: 0.13 | AZ29: =AZ30/(BK30-(L30+P30)) -> 0 | BA29: - | BB29: Taxa | BC29: 0.16 | BD29: =BD30/(BK30-(L30+P30)) -> 0 | BE29: - | BF29: Taxa | BG29: 0.13 | BH29: =BH30/(BK30-(L30+P30)) -> 0 | BI29: - | BJ29: Taxa | BK29: =SUM(T29,X29,AC29,AI29,AM29,AQ29,AU29,AY29,BC29,BG29) -> 1 | BL29: =SUM(T29,X29,AC29,AI29) -> 0.19 | BM29: =SUM(T29,X29,AC29,AI29,AM29) -> 0.32 | BN29: =SUM(U29,Y29,AE29,AJ29,AN29,AR29,AV29,AZ29,BD29,BH29) -> 0.12146345 | BP29: -
J30: GMV | L30: 138541.22 | M30: 150043.78 | N30: =IFERROR(M30-L30,"-") -> 11502.56 | O30: =IFERROR(M30/L30-1,"-") -> 0.083026265 | P30: 119609 | Q30: 130221.82 | R30: =IFERROR(Q30-P30,"-") -> 10612.82 | S30: =IFERROR(Q30/P30-1,"-") -> 0.088729276 | T30: =($BK$30-($L$30+$P$30))*T29 -> 137728.38 | U30: 132201.46 | V30: =IFERROR(U30-T30,"-") -> -5526.9202 | W30: =IFERROR(U30/T30-1,"-") -> -0.040129131 | X30: =($BK$30-($L$30+$P$30))*X29 -> 137728.38 | Y30: 102876.5 | AA30: =IFERROR(Y30-X30,"-") -> -34851.88 | AB30: =IFERROR(Y30/X30-1,"-") -> -0.25304792 | AC30: =($BK$30-($L$30+$P$30))*AC29 -> 229547.3 | AE30: 122347.15 | AF30: =IFERROR(AE30-AC30,"-") -> -107200.15 | AH30: =IFERROR(AE30/AC30-1,"-") -> -0.4670068 | AI30: =($BK$30-($L$30+$P$30))*AI29 -> 367275.68 | AJ30: 123688.18 | AK30: =IFERROR(AJ30-AI30,"-") -> -243587.5 | AL30: =IFERROR(AJ30/AI30-1,"-") -> -0.66322796 | AM30: =($BK$30-($L$30+$P$30))*AM29 -> 596822.98 | AN30: 76518.85 | AO30: =IFERROR(AN30-AM30,"-") -> -520304.13 | AP30: =IFERROR(AN30/AM30-1,"-") -> -0.87178971 | AQ30: =($BK$30-($L$30+$P$30))*AQ29 -> 596822.98 | AS30: =IFERROR(AR30-AQ30,"-") -> -596822.98 | AT30: =IFERROR(AR30/AQ30-1,"-") -> -1 | AU30: =($BK$30-($L$30+$P$30))*AU29 -> 596822.98 | AW30: =IFERROR(AV30-AU30,"-") -> -596822.98 | AX30: =IFERROR(AV30/AU30-1,"-") -> -1 | AY30: =($BK$30-($L$30+$P$30))*AY29 -> 596822.98 | BA30: =IFERROR(AZ30-AY30,"-") -> -596822.98 | BB30: =IFERROR(AZ30/AY30-1,"-") -> -1 | BC30: =($BK$30-($L$30+$P$30))*BC29 -> 734551.36 | BE30: =IFERROR(BD30-BC30,"-") -> -734551.36 | BF30: =IFERROR(BD30/BC30-1,"-") -> -1 | BG30: =($BK$30-($L$30+$P$30))*BG29 -> 596822.98 | BI30: =IFERROR(BH30-BG30,"-") -> -596822.98 | BJ30: =IFERROR(BH30/BG30-1,"-") -> -1 | BK30: 4849096.2 | BL30: =SUM(L30,P30,T30,X30,AC30,AI30) -> 1130430 | BM30: =SUM(L30,P30,T30,X30,AC30,AI30,AM30) -> 1727252.9 | BN30: =SUM(M30,Q30,U30,Y30,AE30,AJ30,AN30,AR30,AV30,AZ30,BD30,BH30) -> 837897.74 | BO30: =IFERROR(BN30/BK30-1,"-") -> -0.82720538 | BP30: 1632825.8 | BQ30: =BK30/BP30-1 -> 1.9697572
J31: Pedidos | L31: =L30/$K$32 -> 1294.7778 | M31: 1236 | N31: =IFERROR(M31-L31,"-") -> -58.777757 | O31: =IFERROR(M31/L31-1,"-") -> -0.04539602 | P31: =P30/$K$32 -> 1117.8411 | Q31: 1061 | R31: =IFERROR(Q31-P31,"-") -> -56.841121 | S31: =IFERROR(Q31/P31-1,"-") -> -0.050849016 | T31: =T30/$K$32 -> 1287.1811 | U31: 1100 | V31: =IFERROR(U31-T31,"-") -> -187.18112 | W31: =IFERROR(U31/T31-1,"-") -> -0.14541941 | X31: =X30/$K$32 -> 1287.1811 | Y31: 881 | AA31: =IFERROR(Y31-X31,"-") -> -406.18112 | AB31: =IFERROR(Y31/X31-1,"-") -> -0.31555864 | AC31: =AC30/$K$32 -> 2145.3019 | AE31: 1012 | AF31: =IFERROR(AE31-AC31,"-") -> -1133.3019 | AH31: =IFERROR(AE31/AC31-1,"-") -> -0.52827152 | AI31: =AI30/$K$32 -> 3432.483 | AJ31: 1058 | AK31: =IFERROR(AJ31-AI31,"-") -> -2374.483 | AL31: =IFERROR(AJ31/AI31-1,"-") -> -0.69176832 | AM31: =AM30/$K$32 -> 5577.7849 | AN31: 665 | AO31: =IFERROR(AN31-AM31,"-") -> -4912.7849 | AP31: =IFERROR(AN31/AM31-1,"-") -> -0.88077704 | AQ31: =AQ30/$K$32 -> 5577.7849 | AS31: =IFERROR(AR31-AQ31,"-") -> -5577.7849 | AT31: =IFERROR(AR31/AQ31-1,"-") -> -1 | AU31: =AU30/$K$32 -> 5577.7849 | AW31: =IFERROR(AV31-AU31,"-") -> -5577.7849 | AX31: =IFERROR(AV31/AU31-1,"-") -> -1 | AY31: =AY30/$K$32 -> 5577.7849 | BA31: =IFERROR(AZ31-AY31,"-") -> -5577.7849 | BB31: =IFERROR(AZ31/AY31-1,"-") -> -1 | BC31: =BC30/$K$32 -> 6864.966 | BE31: =IFERROR(BD31-BC31,"-") -> -6864.966 | BF31: =IFERROR(BD31/BC31-1,"-") -> -1 | BG31: =BG30/$K$32 -> 5577.7849 | BI31: =IFERROR(BH31-BG31,"-") -> -5577.7849 | BJ31: =IFERROR(BH31/BG31-1,"-") -> -1 | BK31: =SUM(L31,P31,T31,X31,AC31,AI31,AM31,AQ31,AU31,AY31,BC31,BG31) -> 45318.656 | BL31: =SUM(L31,P31,T31,X31,AC31,AI31) -> 10564.766 | BM31: =SUM(L31,P31,T31,X31,AC31,AI31,AM31) -> 16142.551 | BN31: =SUM(M31,Q31,U31,Y31,AE31,AJ31,AN31,AR31,AV31,AZ31,BD31,BH31) -> 7013 | BO31: =IFERROR(BN31/BK31-1,"-") -> -0.84525137 | BP31: 15759 | BQ31: =BK31/BP31-1 -> 1.8757317
J32: Ticket Médio | K32: 107 | L32: =L30/L31 -> 107 | M32: =IFERROR(M30/M31,"-") -> 121.39464 | N32: =IFERROR(M32-L32,"-") -> 14.394644 | O32: =IFERROR(M32/L32-1,"-") -> 0.13452938 | P32: =IFERROR(P30/P31,"-") -> 107 | Q32: =IFERROR(Q30/Q31,"-") -> 122.73499 | R32: =IFERROR(Q32-P32,"-") -> 15.734986 | S32: =IFERROR(Q32/P32-1,"-") -> 0.14705594 | T32: =T30/T31 -> 107 | U32: =IFERROR(U30/U31,"-") -> 120.18315 | V32: =IFERROR(U32-T32,"-") -> 13.183145 | W32: =IFERROR(U32/T32-1,"-") -> 0.12320697 | X32: =IFERROR(X30/X31,"-") -> 107 | Y32: =IFERROR(Y30/Y31,"-") -> 116.77242 | AA32: =IFERROR(Y32-X32,"-") -> 9.7724177 | AB32: =IFERROR(Y32/X32-1,"-") -> 0.091331007 | AC32: =AC30/AC31 -> 107 | AE32: =IFERROR(AE30/AE31,"-") -> 120.89639 | AF32: =IFERROR(AE32-AC32,"-") -> 13.896393 | AH32: =IFERROR(AE32/AC32-1,"-") -> 0.12987283 | AI32: =AI30/AI31 -> 107 | AJ32: 116.90754 | AK32: =IFERROR(AJ32-AI32,"-") -> 9.9075425 | AL32: =IFERROR(AJ32/AI32-1,"-") -> 0.092593855 | AM32: =AM30/AM31 -> 107 | AN32: 115.06594 | AO32: =IFERROR(AN32-AM32,"-") -> 8.0659398 | AP32: =IFERROR(AN32/AM32-1,"-") -> 0.075382615 | AQ32: =AQ30/AQ31 -> 107 | AR32: =IFERROR(AR30/AR31,"-") -> - | AS32: =IFERROR(AR32-AQ32,"-") -> - | AT32: =IFERROR(AR32/AQ32-1,"-") -> - | AU32: =AU30/AU31 -> 107 | AV32: =IFERROR(AV30/AV31,"-") -> - | AW32: =IFERROR(AV32-AU32,"-") -> - | AX32: =IFERROR(AV32/AU32-1,"-") -> - | AY32: =AY30/AY31 -> 107 | AZ32: =IFERROR(AZ30/AZ31,"-") -> - | BA32: =IFERROR(AZ32-AY32,"-") -> - | BB32: =IFERROR(AZ32/AY32-1,"-") -> - | BC32: =BC30/BC31 -> 107 | BD32: =IFERROR(BD30/BD31,"-") -> - | BE32: =IFERROR(BD32-BC32,"-") -> - | BF32: =IFERROR(BD32/BC32-1,"-") -> - | BG32: =BG30/BG31 -> 107 | BH32: =IFERROR(BH30/BH31,"-") -> - | BI32: =IFERROR(BH32-BG32,"-") -> - | BJ32: =IFERROR(BH32/BG32-1,"-") -> - | BK32: =BK30/BK31 -> 107 | BL32: =IFERROR(BL30/BL31,"-") -> 107 | BM32: =IFERROR(BM30/BM31,"-") -> 107 | BN32: =BN30/BN31 -> 119.47779 | BO32: =IFERROR(BN32/BK32-1,"-") -> 0.11661486 | BP32: =BP30/BP31 -> 103.61227 | BQ32: =BK32/BP32-1 -> 0.032696201
J33: Receita Hanzo | K33: 0.039 | L33: =IF(L31=0, 0, (L30/L31) * ( MIN(L31, 1000) * 0.049 + MAX(0, MIN(L31, 2500) - 1000) * 0.039 + MAX(0, MIN(L31, 5000) - 2500) * 0.032 + MAX(0, L31 - 5000) * 0.029 )) -> 6473.1076 | M33: =IF(M31=0, 0, (M30/M31) * ( MIN(M31, 1000) * 0.049 + MAX(0, MIN(M31, 2500) - 1000) * 0.039 + MAX(0, MIN(M31, 5000) - 2500) * 0.032 + MAX(0, M31 - 5000) * 0.029 )) -> 7065.6539 | N33: =IFERROR(M33-L33,"-") -> 592.54628 | O33: =IFERROR(M33/L33-1,"-") -> 0.091539693 | P33: =IF(P31=0, 0, (P30/P31) * ( MIN(P31, 1000) * 0.049 + MAX(0, MIN(P31, 2500) - 1000) * 0.039 + MAX(0, MIN(P31, 5000) - 2500) * 0.032 + MAX(0, P31 - 5000) * 0.029 )) -> 5734.751 | Q33: =IF(Q31=0, 0, (Q30/Q31) * ( MIN(Q31, 1000) * 0.049 + MAX(0, MIN(Q31, 2500) - 1000) * 0.039 + MAX(0, MIN(Q31, 5000) - 2500) * 0.032 + MAX(0, Q31 - 5000) * 0.029 )) -> 6306.0008 | R33: =IFERROR(Q33-P33,"-") -> 571.24984 | S33: =IFERROR(Q33/P33-1,"-") -> 0.099611969 | T33: =IF(T31=0, 0, (T30/T31) * ( MIN(T31, 1000) * 0.049 + MAX(0, MIN(T31, 2500) - 1000) * 0.039 + MAX(0, MIN(T31, 5000) - 2500) * 0.032 + MAX(0, T31 - 5000) * 0.029 )) -> 6441.4068 | U33: =IF(U31=0, 0, (U30/U31) * ( MIN(U31, 1000) * 0.049 + MAX(0, MIN(U31, 2500) - 1000) * 0.039 + MAX(0, MIN(U31, 5000) - 2500) * 0.032 + MAX(0, U31 - 5000) * 0.029 )) -> 6357.6884 | V33: =IFERROR(U33-T33,"-") -> -83.718432 | W33: =IFERROR(U33/T33-1,"-") -> -0.012996917 | X33: =IF(X31=0, 0, (X30/X31) * ( MIN(X31, 1000) * 0.049 + MAX(0, MIN(X31, 2500) - 1000) * 0.039 + MAX(0, MIN(X31, 5000) - 2500) * 0.032 + MAX(0, X31 - 5000) * 0.029 )) -> 6441.4068 | Y33: =IF(Y31=0, 0, (Y30/Y31) * ( MIN(Y31, 1000) * 0.049 + MAX(0, MIN(Y31, 2500) - 1000) * 0.039 + MAX(0, MIN(Y31, 5000) - 2500) * 0.032 + MAX(0, Y31 - 5000) * 0.029 )) -> 5040.9485 | AA33: =IFERROR(Y33-X33,"-") -> -1400.4583 | AB33: =IFERROR(Y33/X33-1,"-") -> -0.21741498 | AC33: =IF(AC31=0, 0, (AC30/AC31) * ( MIN(AC31, 1000) * 0.049 + MAX(0, MIN(AC31, 2500) - 1000) * 0.039 + MAX(0, MIN(AC31, 5000) - 2500) * 0.032 + MAX(0, AC31 - 5000) * 0.029 )) -> 10022.345 | AE33: =IF(AE31=0, 0, (AE30/AE31) * ( MIN(AE31, 1000) * 0.049 + MAX(0, MIN(AE31, 2500) - 1000) * 0.039 + MAX(0, MIN(AE31, 5000) - 2500) * 0.032 + MAX(0, AE31 - 5000) * 0.029 )) -> 5980.5028 | AF33: =IFERROR(AE33-AC33,"-") -> -4041.8419 | AH33: =IFERROR(AE33/AC33-1,"-") -> -0.40328307 | AI33: =IF(AI31=0, 0, (AI30/AI31) * ( MIN(AI31, 1000) * 0.049 + MAX(0, MIN(AI31, 2500) - 1000) * 0.039 + MAX(0, MIN(AI31, 5000) - 2500) * 0.032 + MAX(0, AI31 - 5000) * 0.029 )) -> 14695.322 | AJ33: 5992.9144 | AK33: =IFERROR(AJ33-AI33,"-") -> -8702.4073 | AL33: =IFERROR(AJ33/AI33-1,"-") -> -0.59218896 | AM33: =IF(AM31=0, 0, (AM30/AM31) * ( MIN(AM31, 1000) * 0.049 + MAX(0, MIN(AM31, 2500) - 1000) * 0.039 + MAX(0, MIN(AM31, 5000) - 2500) * 0.032 + MAX(0, AM31 - 5000) * 0.029 )) -> 21855.366 | AN33: 3749.4237 | AO33: =IFERROR(AN33-AM33,"-") -> -18105.943 | AP33: =IFERROR(AN33/AM33-1,"-") -> -0.8284438 | AQ33: =IF(AQ31=0, 0, (AQ30/AQ31) * ( MIN(AQ31, 1000) * 0.049 + MAX(0, MIN(AQ31, 2500) - 1000) * 0.039 + MAX(0, MIN(AQ31, 5000) - 2500) * 0.032 + MAX(0, AQ31 - 5000) * 0.029 )) -> 21855.366 | AR33: =IF(AR31=0, 0, (AR30/AR31) * ( MIN(AR31, 1000) * 0.049 + MAX(0, MIN(AR31, 2500) - 1000) * 0.039 + MAX(0, MIN(AR31, 5000) - 2500) * 0.032 + MAX(0, AR31 - 5000) * 0.029 )) -> 0 | AS33: =IFERROR(AR33-AQ33,"-") -> -21855.366 | AT33: =IFERROR(AR33/AQ33-1,"-") -> -1 | AU33: =IF(AU31=0, 0, (AU30/AU31) * ( MIN(AU31, 1000) * 0.049 + MAX(0, MIN(AU31, 2500) - 1000) * 0.039 + MAX(0, MIN(AU31, 5000) - 2500) * 0.032 + MAX(0, AU31 - 5000) * 0.029 )) -> 21855.366 | AV33: =IF(AV31=0, 0, (AV30/AV31) * ( MIN(AV31, 1000) * 0.049 + MAX(0, MIN(AV31, 2500) - 1000) * 0.039 + MAX(0, MIN(AV31, 5000) - 2500) * 0.032 + MAX(0, AV31 - 5000) * 0.029 )) -> 0 | AW33: =IFERROR(AV33-AU33,"-") -> -21855.366 | AX33: =IFERROR(AV33/AU33-1,"-") -> -1 | AY33: =IF(AY31=0, 0, (AY30/AY31) * ( MIN(AY31, 1000) * 0.049 + MAX(0, MIN(AY31, 2500) - 1000) * 0.039 + MAX(0, MIN(AY31, 5000) - 2500) * 0.032 + MAX(0, AY31 - 5000) * 0.029 )) -> 21855.366 | AZ33: =IF(AZ31=0, 0, (AZ30/AZ31) * ( MIN(AZ31, 1000) * 0.049 + MAX(0, MIN(AZ31, 2500) - 1000) * 0.039 + MAX(0, MIN(AZ31, 5000) - 2500) * 0.032 + MAX(0, AZ31 - 5000) * 0.029 )) -> 0 | BA33: =IFERROR(AZ33-AY33,"-") -> -21855.366 | BB33: =IFERROR(AZ33/AY33-1,"-") -> -1 | BC33: =IF(BC31=0, 0, (BC30/BC31) * ( MIN(BC31, 1000) * 0.049 + MAX(0, MIN(BC31, 2500) - 1000) * 0.039 + MAX(0, MIN(BC31, 5000) - 2500) * 0.032 + MAX(0, BC31 - 5000) * 0.029 )) -> 25849.489 | BD33: =IF(BD31=0, 0, (BD30/BD31) * ( MIN(BD31, 1000) * 0.049 + MAX(0, MIN(BD31, 2500) - 1000) * 0.039 + MAX(0, MIN(BD31, 5000) - 2500) * 0.032 + MAX(0, BD31 - 5000) * 0.029 )) -> 0 | BE33: =IFERROR(BD33-BC33,"-") -> -25849.489 | BF33: =IFERROR(BD33/BC33-1,"-") -> -1 | BG33: =IF(BG31=0, 0, (BG30/BG31) * ( MIN(BG31, 1000) * 0.049 + MAX(0, MIN(BG31, 2500) - 1000) * 0.039 + MAX(0, MIN(BG31, 5000) - 2500) * 0.032 + MAX(0, BG31 - 5000) * 0.029 )) -> 21855.366 | BH33: =IF(BH31=0, 0, (BH30/BH31) * ( MIN(BH31, 1000) * 0.049 + MAX(0, MIN(BH31, 2500) - 1000) * 0.039 + MAX(0, MIN(BH31, 5000) - 2500) * 0.032 + MAX(0, BH31 - 5000) * 0.029 )) -> 0 | BI33: =IFERROR(BH33-BG33,"-") -> -21855.366 | BJ33: =IFERROR(BH33/BG33-1,"-") -> -1 | BK33: =SUM(L33,P33,T33,X33,AC33,AI33,AM33,AQ33,AU33,AY33,BC33,BG33) -> 184934.66 | BL33: =SUM(L33,P33,T33,X33,AC33,AI33) -> 49808.339 | BM33: =SUM(L33,P33,T33,X33,AC33,AI33,AM33) -> 71663.705 | BN33: =SUM(M33,Q33,U33,Y33,AE33,AJ33,AN33,AR33,AV33,AZ33,BD33,BH33) -> 40493.132 | BO33: =IFERROR(BN33/BK33-1,"-") -> -0.78104087 | BP33: =BP30*0.39 -> 636802.06 | BQ33: =BK33/BP33 -> 0.29041153
J35: FROOTY (2) | L35: jan | M35: jan (real) | N35: Diferença (jan) | O35: Comparativo (jan) | P35: fev | Q35: fev (real) | R35: Diferença (fev) | S35: Comparativo (fev) | T35: mar | U35: mar (real) | V35: Diferença (mar) | W35: Comparativo (mar) | X35: abr | Y35: abr (real) | AA35: Diferença (abr) | AB35: Comparativo (abr) | AC35: mai | AE35: mai (real) | AF35: Diferença (mai) | AH35: Comparativo (mai) | AI35: jun | AJ35: jun (real) | AK35: Diferença (jun) | AL35: Comparativo (jun) | AM35: jul | AN35: jul (real) | AO35: Diferença (jul) | AP35: Comparativo (jul) | AQ35: ago | AR35: ago (real) | AS35: Diferença (ago) | AT35: Comparativo (ago) | AU35: set | AV35: set (real) | AW35: Diferença (set) | AX35: Comparativo (set) | AY35: out | AZ35: out (real) | BA35: Diferença (out) | BB35: Comparativo (out) | BC35: nov | BD35: nov (real) | BE35: Diferença (nov) | BF35: Comparativo (nov) | BG35: dez | BH35: dez (real) | BI35: Diferença (dez) | BJ35: Comparativo (dez) | BK35: 2026 (Projeção) | BL35: 2026 (Projeção Jun) | BM35: 2026 (Projeção até Jul) | BN35: 2026 (real) | BO35: 2026 (Projeção x Real) | BP35: 2025 | BQ35: -
B37: 6 | C37: GULA GULA | D37: =17000*12 -> 204000 | E37: 170 | F37: =E37*D37 -> 34680000 | G37: 368854.14 | H37: 5074 | I37: 72.694943 | J37: % do mês no ano | L37: - | M37: - | N37: - | O37: Taxa | P37: - | Q37: - | R37: - | S37: Taxa | U37: - | V37: - | W37: Taxa | Y37: - | AA37: - | AB37: Taxa | AC37: 0.02 | AE37: =AE38/(BK38-(L38+P38+T38+X38)) -> 0 | AF37: - | AH37: Taxa | AI37: 0.04 | AJ37: 0 | AK37: - | AL37: Taxa | AM37: 0.07 | AN37: 0 | AO37: - | AP37: Taxa | AQ37: 0.11 | AR37: =AR38/(BK38-(L38+P38+T38+X38)) -> 0 | AS37: - | AT37: Taxa | AU37: 0.15 | AV37: =AV38/(BK38-(L38+P38+T38+X38)) -> 0 | AW37: - | AX37: Taxa | AY37: 0.2 | AZ37: =AZ38/(BK38-(L38+P38+T38+X38)) -> 0 | BA37: - | BB37: Taxa | BC37: 0.2 | BD37: =BD38/(BK38-(L38+P38+T38+X38)) -> 0 | BE37: - | BF37: Taxa | BG37: 0.21 | BH37: =BH38/(BK38-(L38+P38+T38+X38)) -> 0 | BI37: - | BJ37: Taxa | BK37: =SUM(AC37,AI37,AM37,AQ37,AU37,AY37,BC37,BG37) -> 1 | BL37: =SUM(AC37,AI37) -> 0.06 | BM37: =SUM(T37,X37,AC37,AI37,AM37) -> 0.13 | BN37: =SUM(AE37,AJ37,AN37,AR37,AV37,AZ37,BD37,BH37) -> 0 | BP37: -
J38: GMV | L38: 0 | M38: 232.36 | N38: =IFERROR(M38-L38,"-") -> 232.36 | O38: =IFERROR(M38/L38-1,"-") -> - | P38: 0 | Q38: 367.46 | R38: =IFERROR(Q38-P38,"-") -> 367.46 | S38: =IFERROR(Q38/P38-1,"-") -> - | T38: =($BK$38-($L$38+$P$38))*T37 -> 0 | U38: 177.46 | V38: =IFERROR(U38-T38,"-") -> 177.46 | W38: =IFERROR(U38/T38-1,"-") -> - | X38: =($BK$38-($L$38+$P$38))*X37 -> 0 | Y38: 82.24 | AA38: =IFERROR(Y38-X38,"-") -> 82.24 | AB38: =IFERROR(Y38/X38-1,"-") -> - | AC38: =($BK$38-($L$38+$P$38+$T$38+$X$38))*AC37 -> 1000 | AF38: =IFERROR(AE38-AC38,"-") -> -1000 | AH38: =IFERROR(AE38/AC38-1,"-") -> -1 | AI38: =($BK$38-($L$38+$P$38))*AI37 -> 2000 | AJ38: 0 | AK38: =IFERROR(AJ38-AI38,"-") -> -2000 | AL38: =IFERROR(AJ38/AI38-1,"-") -> -1 | AM38: =($BK$38-($L$38+$P$38))*AM37 -> 3500 | AN38: 0 | AO38: =IFERROR(AN38-AM38,"-") -> -3500 | AP38: =IFERROR(AN38/AM38-1,"-") -> -1 | AQ38: =($BK$38-($L$38+$P$38))*AQ37 -> 5500 | AS38: =IFERROR(AR38-AQ38,"-") -> -5500 | AT38: =IFERROR(AR38/AQ38-1,"-") -> -1 | AU38: =($BK$38-($L$38+$P$38))*AU37 -> 7500 | AW38: =IFERROR(AV38-AU38,"-") -> -7500 | AX38: =IFERROR(AV38/AU38-1,"-") -> -1 | AY38: =($BK$38-($L$38+$P$38))*AY37 -> 10000 | BA38: =IFERROR(AZ38-AY38,"-") -> -10000 | BB38: =IFERROR(AZ38/AY38-1,"-") -> -1 | BC38: =($BK$38-($L$38+$P$38))*BC37 -> 10000 | BE38: =IFERROR(BD38-BC38,"-") -> -10000 | BF38: =IFERROR(BD38/BC38-1,"-") -> -1 | BG38: =($BK$38-($L$38+$P$38))*BG37 -> 10500 | BI38: =IFERROR(BH38-BG38,"-") -> -10500 | BJ38: =IFERROR(BH38/BG38-1,"-") -> -1 | BK38: 50000 | BL38: =SUM(L38,P38,T38,X38,AC38,AI38) -> 3000 | BM38: =SUM(L38,P38,T38,X38,AC38,AI38,AM38) -> 6500 | BN38: =SUM(M38,Q38,U38,Y38,AE38,AJ38,AN38,AR38,AV38,AZ38,BD38,BH38) -> 859.52 | BO38: =IFERROR(BN38/BK38-1,"-") -> -0.9828096 | BP38: - | BQ38: =IFERROR((BK38/BP38),"-") -> -
J39: Pedidos | L39: =L38/$K$40 -> 0 | M39: 16 | N39: =IFERROR(M39-L39,"-") -> 16 | O39: =IFERROR(M39/L39-1,"-") -> - | P39: =P38/$K$40 -> 0 | Q39: 122 | R39: =IFERROR(Q39-P39,"-") -> 122 | S39: =IFERROR(Q39/P39-1,"-") -> - | T39: =T38/$K$40 -> 0 | U39: 31 | V39: =IFERROR(U39-T39,"-") -> 31 | W39: =IFERROR(U39/T39-1,"-") -> - | X39: =X38/$K$40 -> 0 | Y39: 2 | AA39: =IFERROR(Y39-X39,"-") -> 2 | AB39: =IFERROR(Y39/X39-1,"-") -> - | AC39: =AC38/$K$40 -> 16.666667 | AF39: =IFERROR(AE39-AC39,"-") -> -16.666667 | AH39: =IFERROR(AE39/AC39-1,"-") -> -1 | AI39: =AI38/$K$40 -> 33.333333 | AJ39: 0 | AK39: =IFERROR(AJ39-AI39,"-") -> -33.333333 | AL39: =IFERROR(AJ39/AI39-1,"-") -> -1 | AM39: =AM38/$K$40 -> 58.333333 | AN39: 0 | AO39: =IFERROR(AN39-AM39,"-") -> -58.333333 | AP39: =IFERROR(AN39/AM39-1,"-") -> -1 | AQ39: =AQ38/$K$40 -> 91.666667 | AS39: =IFERROR(AR39-AQ39,"-") -> -91.666667 | AT39: =IFERROR(AR39/AQ39-1,"-") -> -1 | AU39: =AU38/$K$40 -> 125 | AW39: =IFERROR(AV39-AU39,"-") -> -125 | AX39: =IFERROR(AV39/AU39-1,"-") -> -1 | AY39: =AY38/$K$40 -> 166.66667 | BA39: =IFERROR(AZ39-AY39,"-") -> -166.66667 | BB39: =IFERROR(AZ39/AY39-1,"-") -> -1 | BC39: =BC38/$K$40 -> 166.66667 | BE39: =IFERROR(BD39-BC39,"-") -> -166.66667 | BF39: =IFERROR(BD39/BC39-1,"-") -> -1 | BG39: =BG38/$K$40 -> 175 | BI39: =IFERROR(BH39-BG39,"-") -> -175 | BJ39: =IFERROR(BH39/BG39-1,"-") -> -1 | BK39: =SUM(L39,P39,T39,X39,AC39,AI39,AM39,AQ39,AU39,AY39,BC39,BG39) -> 833.33333 | BL39: =SUM(L39,P39,T39,X39,AC39,AI39) -> 50 | BM39: =SUM(L39,P39,T39,X39,AC39,AI39,AM39) -> 108.33333 | BN39: =SUM(M39,Q39,U39,Y39,AE39,AJ39,AN39,AR39,AV39,AZ39,BD39,BH39) -> 171 | BO39: =IFERROR(BN39/BK39-1,"-") -> -0.7948 | BP39: - | BQ39: =IFERROR((BK39/BP39),"-") -> - | CE39: l
J40: Ticket Médio | K40: 60 | L40: 60 | M40: =IFERROR(M38/M39,"-") -> 14.5225 | N40: =IFERROR(M40-L40,"-") -> -45.4775 | O40: =IFERROR(M40/L40-1,"-") -> -0.75795833 | P40: 60 | Q40: =IFERROR(Q38/Q39,"-") -> 3.0119672 | R40: =IFERROR(Q40-P40,"-") -> -56.988033 | S40: =IFERROR(Q40/P40-1,"-") -> -0.94980055 | T40: 60 | U40: =IFERROR(U38/U39,"-") -> 5.7245161 | V40: =IFERROR(U40-T40,"-") -> -54.275484 | W40: =IFERROR(U40/T40-1,"-") -> -0.9045914 | X40: 60 | Y40: =Y38/Y39 -> 41.12 | AA40: =IFERROR(Y40-X40,"-") -> -18.88 | AB40: =IFERROR(Y40/X40-1,"-") -> -0.31466667 | AC40: =AC38/AC39 -> 60 | AE40: =IFERROR(AE38/AE39,"-") -> - | AF40: =IFERROR(AE40-AC40,"-") -> - | AH40: =IFERROR(AE40/AC40-1,"-") -> - | AI40: =AI38/AI39 -> 60 | AJ40: - | AK40: =IFERROR(AJ40-AI40,"-") -> - | AL40: =IFERROR(AJ40/AI40-1,"-") -> - | AM40: =AM38/AM39 -> 60 | AN40: - | AO40: =IFERROR(AN40-AM40,"-") -> - | AP40: =IFERROR(AN40/AM40-1,"-") -> - | AQ40: =AQ38/AQ39 -> 60 | AR40: =IFERROR(AR38/AR39,"-") -> - | AS40: =IFERROR(AR40-AQ40,"-") -> - | AT40: =IFERROR(AR40/AQ40-1,"-") -> - | AU40: =AU38/AU39 -> 60 | AV40: =IFERROR(AV38/AV39,"-") -> - | AW40: =IFERROR(AV40-AU40,"-") -> - | AX40: =IFERROR(AV40/AU40-1,"-") -> - | AY40: =AY38/AY39 -> 60 | AZ40: =IFERROR(AZ38/AZ39,"-") -> - | BA40: =IFERROR(AZ40-AY40,"-") -> - | BB40: =IFERROR(AZ40/AY40-1,"-") -> - | BC40: =BC38/BC39 -> 60 | BD40: =IFERROR(BD38/BD39,"-") -> - | BE40: =IFERROR(BD40-BC40,"-") -> - | BF40: =IFERROR(BD40/BC40-1,"-") -> - | BG40: =BG38/BG39 -> 60 | BH40: =IFERROR(BH38/BH39,"-") -> - | BI40: =IFERROR(BH40-BG40,"-") -> - | BJ40: =IFERROR(BH40/BG40-1,"-") -> - | BK40: =BK38/BK39 -> 60 | BL40: =IFERROR(BL38/BL39,"-") -> 60 | BM40: =IFERROR(BM38/BM39,"-") -> 60 | BN40: =BN38/BN39 -> 5.0264327 | BO40: =IFERROR(BN40/BK40-1,"-") -> -0.91622612
J41: Receita Hanzo | K41: 0.049 | L41: =L38*$K$41 -> 0 | M41: =M38*$K$41 -> 11.38564 | N41: =IFERROR(M41-L41,"-") -> 11.38564 | O41: =IFERROR(M41/L41-1,"-") -> - | P41: =P38*$K$41 -> 0 | Q41: =Q38*$K$41 -> 18.00554 | R41: =IFERROR(Q41-P41,"-") -> 18.00554 | S41: =IFERROR(Q41/P41-1,"-") -> - | T41: =T38*$K$41 -> 0 | U41: =U38*$K$41 -> 8.69554 | V41: =IFERROR(U41-T41,"-") -> 8.69554 | W41: =IFERROR(U41/T41-1,"-") -> - | X41: =X38*$K$41 -> 0 | Y41: =Y38*$K$41 -> 4.02976 | AA41: =IFERROR(Y41-X41,"-") -> 4.02976 | AB41: =IFERROR(Y41/X41-1,"-") -> - | AC41: =AC38*$K$41 -> 49 | AE41: =AE38*$K$41 -> 0 | AF41: =IFERROR(AE41-AC41,"-") -> -49 | AH41: =IFERROR(AE41/AC41-1,"-") -> -1 | AI41: =AI38*$K$41 -> 98 | AJ41: 0 | AK41: =IFERROR(AJ41-AI41,"-") -> -98 | AL41: =IFERROR(AJ41/AI41-1,"-") -> -1 | AM41: =AM38*$K$41 -> 171.5 | AN41: 0 | AO41: =IFERROR(AN41-AM41,"-") -> -171.5 | AP41: =IFERROR(AN41/AM41-1,"-") -> -1 | AQ41: =AQ38*$K$41 -> 269.5 | AR41: =AR38*$K$41 -> 0 | AS41: =IFERROR(AR41-AQ41,"-") -> -269.5 | AT41: =IFERROR(AR41/AQ41-1,"-") -> -1 | AU41: =AU38*$K$41 -> 367.5 | AV41: =AV38*$K$41 -> 0 | AW41: =IFERROR(AV41-AU41,"-") -> -367.5 | AX41: =IFERROR(AV41/AU41-1,"-") -> -1 | AY41: =AY38*$K$41 -> 490 | AZ41: =AZ38*$K$41 -> 0 | BA41: =IFERROR(AZ41-AY41,"-") -> -490 | BB41: =IFERROR(AZ41/AY41-1,"-") -> -1 | BC41: =BC38*$K$41 -> 490 | BD41: =BD38*$K$41 -> 0 | BE41: =IFERROR(BD41-BC41,"-") -> -490 | BF41: =IFERROR(BD41/BC41-1,"-") -> -1 | BG41: =BG38*$K$41 -> 514.5 | BH41: =BH38*$K$41 -> 0 | BI41: =IFERROR(BH41-BG41,"-") -> -514.5 | BJ41: =IFERROR(BH41/BG41-1,"-") -> -1 | BK41: =SUM(L41,P41,T41,X41,AC41,AI41,AM41,AQ41,AU41,AY41,BC41,BG41) -> 2450 | BL41: =SUM(L41,P41,T41,X41,AC41,AI41) -> 147 | BM41: =SUM(L41,P41,T41,X41,AC41,AI41,AM41) -> 318.5 | BN41: =SUM(M41,Q41,U41,Y41,AE41,AJ41,AN41,AR41,AV41,AZ41,BD41,BH41) -> 42.11648 | BO41: =IFERROR(BN41/BK41-1,"-") -> -0.9828096 | BP41: - | BQ41: =IFERROR((BK41/BP41),"-") -> -
J43: GULA GULA (10) | L43: jan | M43: jan (real) | N43: Diferença (jan) | O43: Comparativo (jan) | P43: fev | Q43: fev (real) | R43: Diferença (fev) | S43: Comparativo (fev) | T43: mar | U43: mar (real) | V43: Diferença (mar) | W43: Comparativo (mar) | X43: abr | Y43: abr (real) | AA43: Diferença (abr) | AB43: Comparativo (abr) | AC43: mai | AE43: mai (real) | AF43: Diferença (mai) | AH43: Comparativo (mai) | AI43: jun | AJ43: jun (real) | AK43: Diferença (jun) | AL43: Comparativo (jun) | AM43: jul | AN43: jul (real) | AO43: Diferença (jul) | AP43: Comparativo (jul) | AQ43: ago | AR43: ago (real) | AS43: Diferença (ago) | AT43: Comparativo (ago) | AU43: set | AV43: set (real) | AW43: Diferença (set) | AX43: Comparativo (set) | AY43: out | AZ43: out (real) | BA43: Diferença (out) | BB43: Comparativo (out) | BC43: nov | BD43: nov (real) | BE43: Diferença (nov) | BF43: Comparativo (nov) | BG43: dez | BH43: dez (real) | BI43: Diferença (dez) | BJ43: Comparativo (dez) | BK43: 2026 (Projeção) | BL43: 2026 (Projeção Jun) | BM43: 2026 (Projeção até Jul) | BN43: 2026 (real) | BO43: 2026 (Projeção x Real) | BP43: 2025
B45: 7 | C45: ITAL'IN HOUSE | J45: Repres. do mês no ano | L45: - | M45: - | N45: - | O45: Taxa | P45: - | Q45: - | R45: - | S45: Taxa | T45: 0.04 | U45: =U46/(BK46-(L46 + P46)) -> 0.051817743 | V45: - | W45: Taxa | X45: 0.05 | Y45: =Y46/(BK46-(L46+P46)) -> 0.037280231 | AA45: - | AB45: Taxa | AC45: 0.05 | AE45: =AE46/(BK46-(L46+P46)) -> 0.052521072 | AF45: - | AH45: Taxa | AI45: 0.08 | AJ45: 0.05844962 | AK45: - | AL45: Taxa | AM45: 0.08 | AN45: 0.026801088 | AO45: - | AP45: Taxa | AQ45: 0.08 | AR45: =AR46/(BK46-(L46+P46)) -> 0 | AS45: - | AT45: Taxa | AU45: 0.13 | AV45: =AV46/(BK46-(L46+P46)) -> 0 | AW45: - | AX45: Taxa | AY45: 0.13 | AZ45: =AZ46/(BK46-(L46+P46)) -> 0 | BA45: - | BB45: Taxa | BC45: 0.23 | BD45: =BD46/(BK46-(L46+P46)) -> 0 | BE45: - | BF45: Taxa | BG45: 0.13 | BH45: =BH46/(BK46-(L46+P46)) -> 0 | BI45: - | BJ45: Taxa | BK45: =SUM(T45,X45,AC45,AI45,AM45,AQ45,AU45,AY45,BC45,BG45) -> 1 | BL45: =SUM(T45,X45,AC45,AI45) -> 0.22 | BM45: =SUM(T45,X45,AC45,AI45,AM45) -> 0.3 | BN45: =SUM(U45,Y45,AE45,AJ45,AN45,AR45,AV45,AZ45,BD45,BH45) -> 0.22686975 | BP45: -
